Workbook

Sheet Cmt Vs Tgt Aug-23
A1: TL/ASM | B1: 1-10 Commitment | F1: ACH TILL 1-10(JULY) | N1: 11-17 Commitment | R1: ACH TILL 11-17 | Z1: 18-28 Commitment | AD1: ACH 18-27 | AL1: Commitment Jul-23 | AP1: ACH Jul-23 | AX1: Last Booking Date
B2: BKGS | C2: IN STOCK | D2: RETAIL | E2: TP | F2: BKGS | G2: % | H2: IN STOCK | I2: % | J2: RETAIL | K2: % | L2: TP | M2: % | N2: BKGS | O2: IN STOCK | P2: RETAIL | Q2: TP | R2: BKGS | S2: % | T2: IN STOCK | U2: % | V2: RETAIL | W2: % | X2: TP | Y2: % | Z2: BKGS | AA2: IN STOCK | AB2: RETAIL | AC2: TP | AD2: BKGS | AE2: % | AF2: IN STOCK | AG2: % | AH2: RETAIL | AI2: % | AJ2: TP | AK2: % | AL2: BKGS | AM2: IN STOCK | AN2: RETAIL | AO2: TP | AP2: BKGS | AQ2: % | AR2: IN STOCK | AS2: % | AT2: RETAIL | AU2: % | AV2: TP | AW2: %
A3: NASEEHA | F3: 6 | G3: =F3/B3 -> #DIV/0! | I3: =H3/C3 -> #DIV/0! | K3: =J3/D3 -> #DIV/0! | M3: =L3/E3 -> #DIV/0! | N3: 4 | O3: 2 | P3: 3 | Q3: 2 | R3: 14 | S3: =R3/N3 -> 3.5 | T3: 1 | U3: =T3/O3 -> 0.5 | V3: 1 | W3: =V3/P3 -> 0.33333333 | X3: 2 | Y3: =X3/Q3 -> 1 | Z3: 6 | AA3: 3 | AB3: 10 | AC3: 8 | AD3: 28 | AE3: =AD3/Z3 -> 4.6666667 | AF3: 1 | AG3: =AF3/AA3 -> 0.33333333 | AH3: 8 | AI3: =AH3/AB3 -> 0.8 | AJ3: 6 | AK3: =AJ3/AC3 -> 0.75 | AN3: 10 | AP3: =F3+R3+AD3 -> 48 | AQ3: =AP3/AL3 -> #DIV/0! | AR3: =H3+T3+AF3 -> 2 | AS3: =AR3/AM3 -> #DIV/0! | AT3: =J3+V3+AH3 -> 9 | AU3: =AT3/AN3 -> 0.9 | AV3: =L3+X3+AJ3 -> 8 | AW3: =AV3/AO3 -> #DIV/0! | AX3: 45134
A4: RISHAD | F4: 10 | G4: =F4/B4 -> #DIV/0! | H4: 1 | I4: =H4/C4 -> #DIV/0! | J4: 4 | K4: =J4/D4 -> #DIV/0! | M4: =L4/E4 -> #DIV/0! | N4: 4 | O4: 2 | P4: 3 | Q4: 2 | R4: 14 | S4: =R4/N4 -> 3.5 | T4: 1 | U4: =T4/O4 -> 0.5 | V4: 1 | W4: =V4/P4 -> 0.33333333 | X4: 2 | Y4: =X4/Q4 -> 1 | Z4: 6 | AA4: 3 | AB4: 10 | AC4: 8 | AD4: 28 | AE4: =AD4/Z4 -> 4.6666667 | AF4: 1 | AG4: =AF4/AA4 -> 0.33333333 | AH4: 8 | AI4: =AH4/AB4 -> 0.8 | AJ4: 6 | AK4: =AJ4/AC4 -> 0.75 | AN4: 13 | AP4: =F4+R4+AD4 -> 52 | AQ4: =AP4/AL4 -> #DIV/0! | AR4: =H4+T4+AF4 -> 3 | AS4: =AR4/AM4 -> #DIV/0! | AT4: =J4+V4+AH4 -> 13 | AU4: =AT4/AN4 -> 1 | AV4: =L4+X4+AJ4 -> 8 | AW4: =AV4/AO4 -> #DIV/0! | AX4: 45134
A5: JISHNU | F5: 3 | G5: =F5/B5 -> #DIV/0! | H5: 1 | I5: =H5/C5 -> #DIV/0! | J5: 4 | K5: =J5/D5 -> #DIV/0! | M5: =L5/E5 -> #DIV/0! | N5: 4 | O5: 3 | P5: 3 | Q5: 3 | R5: 11 | S5: =R5/N5 -> 2.75 | U5: =T5/O5 -> 0 | V5: 1 | W5: =V5/P5 -> 0.33333333 | Y5: =X5/Q5 -> 0 | Z5: 5 | AA5: 3 | AB5: 9 | AC5: 8 | AD5: 15 | AE5: =AD5/Z5 -> 3 | AG5: =AF5/AA5 -> 0 | AH5: 7 | AI5: =AH5/AB5 -> 0.77777778 | AJ5: 7 | AK5: =AJ5/AC5 -> 0.875 | AN5: 13 | AP5: =F5+R5+AD5 -> 29 | AQ5: =AP5/AL5 -> #DIV/0! | AR5: =H5+T5+AF5 -> 1 | AS5: =AR5/AM5 -> #DIV/0! | AT5: =J5+V5+AH5 -> 12 | AU5: =AT5/AN5 -> 0.92307692 | AV5: =L5+X5+AJ5 -> 7 | AW5: =AV5/AO5 -> #DIV/0! | AX5: 45133
A6: JIJEESH | F6: 0 | G6: =F6/B6 -> #DIV/0! | H6: 0 | I6: =H6/C6 -> #DIV/0! | J6: 2 | K6: =J6/D6 -> #DIV/0! | M6: =L6/E6 -> #DIV/0! | N6: 3 | O6: 2 | P6: 2 | Q6: 2 | R6: 2 | S6: =R6/N6 -> 0.66666667 | T6: 2 | U6: =T6/O6 -> 1 | W6: =V6/P6 -> 0 | X6: 1 | Y6: =X6/Q6 -> 0.5 | Z6: 2 | AA6: 2 | AB6: 4 | AC6: 3 | AD6: 2 | AE6: =AD6/Z6 -> 1 | AG6: =AF6/AA6 -> 0 | AH6: 1 | AI6: =AH6/AB6 -> 0.25 | AJ6: 1 | AK6: =AJ6/AC6 -> 0.33333333 | AN6: 7 | AP6: =F6+R6+AD6 -> 4 | AQ6: =AP6/AL6 -> #DIV/0! | AR6: =H6+T6+AF6 -> 2 | AS6: =AR6/AM6 -> #DIV/0! | AT6: =J6+V6+AH6 -> 3 | AU6: =AT6/AN6 -> 0.42857143 | AV6: =L6+X6+AJ6 -> 2 | AW6: =AV6/AO6 -> #DIV/0! | AX6: 45125
A7: SHAGEETH | F7: 4 | G7: =F7/B7 -> #DIV/0! | H7: 2 | I7: =H7/C7 -> #DIV/0! | J7: 1 | K7: =J7/D7 -> #DIV/0! | M7: =L7/E7 -> #DIV/0! | N7: 2 | O7: 2 | P7: 1 | Q7: 1 | R7: 7 | S7: =R7/N7 -> 3.5 | T7: 1 | U7: =T7/O7 -> 0.5 | W7: =V7/P7 -> 0 | Y7: =X7/Q7 -> 0 | Z7: 3 | AA7: 2 | AB7: 7 | AC7: 5 | AD7: 9 | AE7: =AD7/Z7 -> 3 | AF7: 3 | AG7: =AF7/AA7 -> 1.5 | AH7: 5 | AI7: =AH7/AB7 -> 0.71428571 | AJ7: 3 | AK7: =AJ7/AC7 -> 0.6 | AN7: 10 | AP7: =F7+R7+AD7 -> 20 | AQ7: =AP7/AL7 -> #DIV/0! | AR7: =H7+T7+AF7 -> 6 | AS7: =AR7/AM7 -> #DIV/0! | AT7: =J7+V7+AH7 -> 6 | AU7: =AT7/AN7 -> 0.6 | AV7: =L7+X7+AJ7 -> 3 | AW7: =AV7/AO7 -> #DIV/0! | AX7: 45133
A8: KHAYYOOM | F8: 0 | G8: =F8/B8 -> #DIV/0! | H8: 0 | I8: =H8/C8 -> #DIV/0! | J8: 0 | K8: =J8/D8 -> #DIV/0! | M8: =L8/E8 -> #DIV/0! | N8: 1 | O8: 1 | P8: 1 | Q8: 0 | R8: 3 | S8: =R8/N8 -> 3 | U8: =T8/O8 -> 0 | W8: =V8/P8 -> 0 | Y8: =X8/Q8 -> #DIV/0! | Z8: 2 | AA8: 2 | AB8: 2 | AC8: 2 | AD8: 2 | AE8: =AD8/Z8 -> 1 | AG8: =AF8/AA8 -> 0 | AH8: 1 | AI8: =AH8/AB8 -> 0.5 | AK8: =AJ8/AC8 -> 0 | AN8: 3 | AP8: =F8+R8+AD8 -> 5 | AQ8: =AP8/AL8 -> #DIV/0! | AR8: =H8+T8+AF8 -> 0 | AS8: =AR8/AM8 -> #DIV/0! | AT8: =J8+V8+AH8 -> 1 | AU8: =AT8/AN8 -> 0.33333333 | AV8: =L8+X8+AJ8 -> 0 | AW8: =AV8/AO8 -> #DIV/0! | AX8: 45126
A9: MALAPPURAM | B9: =SUM(B3:B8) -> 0 | C9: =SUM(C3:C8) -> 0 | D9: =SUM(D3:D8) -> 0 | E9: =SUM(E3:E8) -> 0 | F9: =SUM(F3:F8) -> 23 | G9: =F9/B9 -> #DIV/0! | H9: =SUM(H3:H8) -> 4 | I9: =H9/C9 -> #DIV/0! | J9: =SUM(J3:J8) -> 11 | K9: =J9/D9 -> #DIV/0! | L9: =SUM(L3:L8) -> 0 | M9: =L9/E9 -> #DIV/0! | N9: =SUM(N3:N8) -> 18 | O9: =SUM(O3:O8) -> 12 | P9: =SUM(P3:P8) -> 13 | Q9: =SUM(Q3:Q8) -> 10 | R9: =SUM(R3:R8) -> 51 | S9: =R9/N9 -> 2.8333333 | T9: =SUM(T3:T8) -> 5 | U9: =T9/O9 -> 0.41666667 | V9: =SUM(V3:V8) -> 3 | W9: =V9/P9 -> 0.23076923 | X9: =SUM(X3:X8) -> 5 | Y9: =X9/Q9 -> 0.5 | Z9: =SUM(Z3:Z8) -> 24 | AA9: =SUM(AA3:AA8) -> 15 | AB9: =SUM(AB3:AB8) -> 42 | AC9: =SUM(AC3:AC8) -> 34 | AD9: =SUM(AD3:AD8) -> 84 | AE9: =AD9/Z9 -> 3.5 | AF9: =SUM(AF3:AF8) -> 5 | AG9: =AF9/AA9 -> 0.33333333 | AH9: =SUM(AH3:AH8) -> 30 | AI9: =AH9/AB9 -> 0.71428571 | AJ9: =SUM(AJ3:AJ8) -> 23 | AK9: =AJ9/AC9 -> 0.67647059 | AL9: =SUM(AL3:AL8) -> 0 | AM9: =SUM(AM3:AM8) -> 0 | AN9: =SUM(AN3:AN8) -> 56 | AO9: =SUM(AO3:AO8) -> 0 | AP9: =SUM(AP3:AP8) -> 158 | AQ9: =AP9-AL9 -> 158 | AR9: =SUM(AR3:AR8) -> 14 | AS9: =AR9-AM9 -> 14 | AT9: =SUM(AT3:AT8) -> 44 | AU9: =AT9/AN9 -> 0.78571429 | AV9: =SUM(AV3:AV8) -> 28 | AW9: =AV9/AO9 -> #DIV/0!
A10: SANEESH | F10: 11 | G10: =F10/B10 -> #DIV/0! | I10: =H10/C10 -> #DIV/0! | J10: 3 | K10: =J10/D10 -> #DIV/0! | M10: =L10/E10 -> #DIV/0! | N10: 3 | O10: 2 | P10: 3 | Q10: 2 | R10: 7 | S10: =R10/N10 -> 2.3333333 | T10: 2 | U10: =T10/O10 -> 1 | W10: =V10/P10 -> 0 | Y10: =X10/Q10 -> 0 | Z10: 10 | AA10: 2 | AB10: 10 | AC10: 8 | AD10: 21 | AE10: =AD10/Z10 -> 2.1 | AG10: =AF10/AA10 -> 0 | AH10: 10 | AI10: =AH10/AB10 -> 1 | AJ10: 8 | AK10: =AJ10/AC10 -> 1 | AN10: 15 | AP10: =F10+R10+AD10 -> 39 | AQ10: =AP10/AL10 -> #DIV/0! | AR10: =H10+T10+AF10 -> 2 | AS10: =AR10/AM10 -> #DIV/0! | AT10: =J10+V10+AH10 -> 13 | AU10: =AT10/AN10 -> 0.86666667 | AV10: =L10+X10+AJ10 -> 8 | AW10: =AV10/AO10 -> #DIV/0! | AX10: 45134
A11: EDAPPAL | F11: 11 | G11: =F11/B11 -> #DIV/0! | I11: =H11/C11 -> #DIV/0! | J11: 2 | K11: =J11/D11 -> #DIV/0! | M11: =L11/E11 -> #DIV/0! | N11: 3 | O11: 2 | P11: 3 | Q11: 2 | R11: 7 | S11: =R11/N11 -> 2.3333333 | T11: 1 | U11: =T11/O11 -> 0.5 | V11: 1 | W11: =V11/P11 -> 0.33333333 | Y11: =X11/Q11 -> 0 | Z11: 8 | AA11: 2 | AB11: 8 | AC11: 6 | AD11: 6 | AE11: =AD11/Z11 -> 0.75 | AF11: 2 | AG11: =AF11/AA11 -> 1 | AH11: 3 | AI11: =AH11/AB11 -> 0.375 | AJ11: 3 | AK11: =AJ11/AC11 -> 0.5 | AN11: 10 | AP11: =F11+R11+AD11 -> 24 | AQ11: =AP11/AL11 -> #DIV/0! | AR11: =H11+T11+AF11 -> 3 | AS11: =AR11/AM11 -> #DIV/0! | AT11: =J11+V11+AH11 -> 6 | AU11: =AT11/AN11 -> 0.6 | AV11: =L11+X11+AJ11 -> 3 | AW11: =AV11/AO11 -> #DIV/0! | AX11: 45129
A12: SUMESH | F12: 2 | G12: =F12/B12 -> #DIV/0! | I12: =H12/C12 -> #DIV/0! | K12: =J12/D12 -> #DIV/0! | M12: =L12/E12 -> #DIV/0! | N12: 2 | O12: 1 | P12: 1 | Q12: 1 | R12: 2 | S12: =R12/N12 -> 1 | U12: =T12/O12 -> 0 | W12: =V12/P12 -> 0 | Y12: =X12/Q12 -> 0 | Z12: 4 | AA12: 2 | AB12: 4 | AC12: 3 | AD12: 6 | AE12: =AD12/Z12 -> 1.5 | AG12: =AF12/AA12 -> 0 | AH12: 1 | AI12: =AH12/AB12 -> 0.25 | AJ12: 1 | AK12: =AJ12/AC12 -> 0.33333333 | AN12: 6 | AP12: =F12+R12+AD12 -> 10 | AQ12: =AP12/AL12 -> #DIV/0! | AR12: =H12+T12+AF12 -> 0 | AS12: =AR12/AM12 -> #DIV/0! | AT12: =J12+V12+AH12 -> 1 | AU12: =AT12/AN12 -> 0.16666667 | AV12: =L12+X12+AJ12 -> 1 | AW12: =AV12/AO12 -> #DIV/0! | AX12: 45132
A13: KOTTAKKAL | B13: =SUM(B10:B12) -> 0 | C13: =SUM(C10:C12) -> 0 | D13: =SUM(D10:D12) -> 0 | E13: =SUM(E10:E12) -> 0 | F13: =SUM(F10:F12) -> 24 | G13: =F13/B13 -> #DIV/0! | H13: =SUM(H10:H12) -> 0 | I13: =H13/C13 -> #DIV/0! | J13: =SUM(J10:J12) -> 5 | K13: =J13/D13 -> #DIV/0! | L13: =SUM(L10:L12) -> 0 | M13: =L13/E13 -> #DIV/0! | N13: =SUM(N10:N12) -> 8 | O13: =SUM(O10:O12) -> 5 | P13: =SUM(P10:P12) -> 7 | Q13: =SUM(Q10:Q12) -> 5 | R13: =SUM(R10:R12) -> 16 | S13: =R13/N13 -> 2 | T13: =SUM(T10:T12) -> 3 | U13: =T13/O13 -> 0.6 | V13: =SUM(V10:V12) -> 1 | W13: =V13/P13 -> 0.14285714 | X13: =SUM(X10:X12) -> 0 | Y13: =X13/Q13 -> 0 | Z13: =SUM(Z10:Z12) -> 22 | AA13: =SUM(AA10:AA12) -> 6 | AB13: =SUM(AB10:AB12) -> 22 | AC13: =SUM(AC10:AC12) -> 17 | AD13: =SUM(AD10:AD12) -> 33 | AE13: =AD13/Z13 -> 1.5 | AF13: =SUM(AF10:AF12) -> 2 | AG13: =AF13/AA13 -> 0.33333333 | AH13: =SUM(AH10:AH12) -> 14 | AI13: =AH13/AB13 -> 0.63636364 | AJ13: =SUM(AJ10:AJ12) -> 12 | AK13: =AJ13/AC13 -> 0.70588235 | AL13: =SUM(AL10:AL12) -> 0 | AM13: =SUM(AM10:AM12) -> 0 | AN13: =SUM(AN10:AN12) -> 31 | AO13: =SUM(AO10:AO12) -> 0 | AP13: =SUM(AP10:AP12) -> 73 | AQ13: =AP13-AL13 -> 73 | AR13: =SUM(AR10:AR12) -> 5 | AS13: =AR13-AM13 -> 5 | AT13: =SUM(AT10:AT12) -> 20 | AU13: =AT13-AN13 -> -11 | AV13: =SUM(AV10:AV12) -> 12 | AW13: =AV13/AO13 -> #DIV/0!
A14: TOTAL | B14: =SUM(B13+B9) -> 0 | C14: =SUM(C13+C9) -> 0 | D14: =SUM(D13+D9) -> 0 | E14: =SUM(E13+E9) -> 0 | F14: =SUM(F13+F9) -> 47 | G14: =F14/B14 -> #DIV/0! | H14: =SUM(H13+H9) -> 4 | I14: =H14/C14 -> #DIV/0! | J14: =SUM(J13+J9) -> 16 | K14: =J14/D14 -> #DIV/0! | L14: =SUM(L13+L9) -> 0 | M14: =L14/E14 -> #DIV/0! | N14: =SUM(N13+N9) -> 26 | O14: =SUM(O13+O9) -> 17 | P14: =SUM(P13+P9) -> 20 | Q14: =SUM(Q13+Q9) -> 15 | R14: =SUM(R13+R9) -> 67 | S14: =R14/N14 -> 2.5769231 | T14: =SUM(T13+T9) -> 8 | U14: =T14/O14 -> 0.47058824 | V14: =SUM(V13+V9) -> 4 | W14: =V14/P14 -> 0.2 | X14: =SUM(X13+X9) -> 5 | Y14: =X14/Q14 -> 0.33333333 | Z14: =SUM(Z13+Z9) -> 46 | AA14: =SUM(AA13+AA9) -> 21 | AB14: =SUM(AB13+AB9) -> 64 | AC14: =SUM(AC13+AC9) -> 51 | AD14: =SUM(AD13+AD9) -> 117 | AE14: =AD14/Z14 -> 2.5434783 | AF14: =SUM(AF13+AF9) -> 7 | AG14: =AF14/AA14 -> 0.33333333 | AH14: =SUM(AH13+AH9) -> 44 | AI14: =AH14/AB14 -> 0.6875 | AJ14: =SUM(AJ13+AJ9) -> 35 | AK14: =AJ14/AC14 -> 0.68627451 | AL14: =SUM(AL13+AL9) -> 0 | AM14: =SUM(AM13+AM9) -> 0 | AN14: =SUM(AN13+AN9) -> 87 | AO14: =SUM(AO13+AO9) -> 0 | AP14: =SUM(AP13+AP9) -> 231 | AQ14: =AP14-AL14 -> 231 | AR14: =SUM(AR13+AR9) -> 19 | AS14: =AR14-AM14 -> 19 | AT14: =SUM(AT13+AT9) -> 64 | AU14: =AT14-AN14 -> -23 | AV14: =SUM(AV13+AV9) -> 40 | AW14: =AV14/AO14 -> #DIV/0!

Sheet Cmt Vs Tgt Jul-23
A1: TL/ASM | B1: 1-10 Commitment | F1: ACH TILL 1-10(JULY) | N1: 11-17 Commitment | R1: ACH TILL 11-17 | Z1: 18-28 Commitment | AD1: ACH 18-27 | AL1: Commitment Jul-23 | AP1: ACH Jul-23 | AX1: Last Booking Date
B2: BKGS | C2: IN STOCK | D2: RETAIL | E2: TP | F2: BKGS | G2: % | H2: IN STOCK | I2: % | J2: RETAIL | K2: % | L2: TP | M2: % | N2: BKGS | O2: IN STOCK | P2: RETAIL | Q2: TP | R2: BKGS | S2: % | T2: IN STOCK | U2: % | V2: RETAIL | W2: % | X2: TP | Y2: % | Z2: BKGS | AA2: IN STOCK | AB2: RETAIL | AC2: TP | AD2: BKGS | AE2: % | AF2: IN STOCK | AG2: % | AH2: RETAIL | AI2: % | AJ2: TP | AK2: % | AL2: BKGS | AM2: IN STOCK | AN2: RETAIL | AO2: TP | AP2: BKGS | AQ2: % | AR2: IN STOCK | AS2: % | AT2: RETAIL | AU2: % | AV2: TP | AW2: %
A3: RISHAD | B3: 4 | C3: 2 | D3: 1 | E3: 1 | F3: 5 | G3: =F3/B3 -> 1.25 | H3: 0 | I3: =H3/C3 -> 0 | J3: 1 | K3: =J3/D3 -> 1 | M3: =L3/E3 -> 0 | N3: 4 | O3: 2 | P3: 3 | Q3: 2 | R3: 14 | S3: =R3/N3 -> 3.5 | T3: 1 | U3: =T3/O3 -> 0.5 | V3: 1 | W3: =V3/P3 -> 0.33333333 | X3: 2 | Y3: =X3/Q3 -> 1 | Z3: 6 | AA3: 3 | AB3: 10 | AC3: 8 | AD3: 28 | AE3: =AD3/Z3 -> 4.6666667 | AF3: 1 | AG3: =AF3/AA3 -> 0.33333333 | AH3: 8 | AI3: =AH3/AB3 -> 0.8 | AJ3: 6 | AK3: =AJ3/AC3 -> 0.75 | AL3: =B3+N3+Z3 -> 14 | AM3: =C3+O3+AA3 -> 7 | AN3: 12 | AO3: 10 | AP3: =F3+R3+AD3 -> 47 | AQ3: =AP3/AL3 -> 3.3571429 | AR3: =H3+T3+AF3 -> 2 | AS3: =AR3/AM3 -> 0.28571429 | AT3: =J3+V3+AH3 -> 10 | AU3: =AT3/AN3 -> 0.83333333 | AV3: =L3+X3+AJ3 -> 8 | AW3: =AV3/AO3 -> 0.8 | AX3: 45134
A4: JISHNU | B4: 4 | C4: 1 | D4: 1 | E4: 1 | F4: 4 | G4: =F4/B4 -> 1 | H4: 0 | I4: =H4/C4 -> 0 | J4: 2 | K4: =J4/D4 -> 2 | L4: 5 | M4: =L4/E4 -> 5 | N4: 4 | O4: 3 | P4: 3 | Q4: 3 | R4: 11 | S4: =R4/N4 -> 2.75 | U4: =T4/O4 -> 0 | V4: 1 | W4: =V4/P4 -> 0.33333333 | Y4: =X4/Q4 -> 0 | Z4: 5 | AA4: 3 | AB4: 9 | AC4: 8 | AD4: 15 | AE4: =AD4/Z4 -> 3 | AG4: =AF4/AA4 -> 0 | AH4: 7 | AI4: =AH4/AB4 -> 0.77777778 | AJ4: 7 | AK4: =AJ4/AC4 -> 0.875 | AL4: =B4+N4+Z4 -> 13 | AM4: =C4+O4+AA4 -> 7 | AN4: 12 | AO4: 10 | AP4: =F4+R4+AD4 -> 30 | AQ4: =AP4/AL4 -> 2.3076923 | AR4: =H4+T4+AF4 -> 0 | AS4: =AR4/AM4 -> 0 | AT4: =J4+V4+AH4 -> 10 | AU4: =AT4/AN4 -> 0.83333333 | AV4: =L4+X4+AJ4 -> 12 | AW4: =AV4/AO4 -> 1.2 | AX4: 45133
A5: JIJEESH | B5: 2 | C5: 2 | D5: 0 | E5: 1 | F5: 2 | G5: =F5/B5 -> 1 | H5: 0 | I5: =H5/C5 -> 0 | J5: 1 | K5: =J5/D5 -> #DIV/0! | M5: =L5/E5 -> 0 | N5: 3 | O5: 2 | P5: 2 | Q5: 2 | R5: 2 | S5: =R5/N5 -> 0.66666667 | T5: 2 | U5: =T5/O5 -> 1 | W5: =V5/P5 -> 0 | X5: 1 | Y5: =X5/Q5 -> 0.5 | Z5: 2 | AA5: 2 | AB5: 4 | AC5: 3 | AD5: 2 | AE5: =AD5/Z5 -> 1 | AG5: =AF5/AA5 -> 0 | AH5: 1 | AI5: =AH5/AB5 -> 0.25 | AJ5: 1 | AK5: =AJ5/AC5 -> 0.33333333 | AL5: =B5+N5+Z5 -> 7 | AM5: =C5+O5+AA5 -> 6 | AN5: 5 | AO5: 4 | AP5: =F5+R5+AD5 -> 6 | AQ5: =AP5/AL5 -> 0.85714286 | AR5: =H5+T5+AF5 -> 2 | AS5: =AR5/AM5 -> 0.33333333 | AT5: =J5+V5+AH5 -> 2 | AU5: =AT5/AN5 -> 0.4 | AV5: =L5+X5+AJ5 -> 2 | AW5: =AV5/AO5 -> 0.5 | AX5: 45125
A6: SHAGEETH | B6: 2 | C6: 1 | D6: 1 | E6: 1 | F6: 0 | G6: =F6/B6 -> 0 | H6: 0 | I6: =H6/C6 -> 0 | K6: =J6/D6 -> 0 | L6: 1 | M6: =L6/E6 -> 1 | N6: 2 | O6: 2 | P6: 1 | Q6: 1 | R6: 7 | S6: =R6/N6 -> 3.5 | T6: 1 | U6: =T6/O6 -> 0.5 | W6: =V6/P6 -> 0 | Y6: =X6/Q6 -> 0 | Z6: 3 | AA6: 2 | AB6: 7 | AC6: 5 | AD6: 9 | AE6: =AD6/Z6 -> 3 | AF6: 3 | AG6: =AF6/AA6 -> 1.5 | AH6: 5 | AI6: =AH6/AB6 -> 0.71428571 | AJ6: 3 | AK6: =AJ6/AC6 -> 0.6 | AL6: =B6+N6+Z6 -> 7 | AM6: =C6+O6+AA6 -> 5 | AN6: 8 | AO6: 7 | AP6: =F6+R6+AD6 -> 16 | AQ6: =AP6/AL6 -> 2.2857143 | AR6: =H6+T6+AF6 -> 4 | AS6: =AR6/AM6 -> 0.8 | AT6: =J6+V6+AH6 -> 5 | AU6: =AT6/AN6 -> 0.625 | AV6: =L6+X6+AJ6 -> 4 | AW6: =AV6/AO6 -> 0.57142857 | AX6: 45133
A7: KHAYYOOM | B7: 1 | C7: 1 | D7: 0 | E7: 0 | F7: 0 | G7: =F7/B7 -> 0 | H7: 0 | I7: =H7/C7 -> 0 | K7: =J7/D7 -> #DIV/0! | M7: =L7/E7 -> #DIV/0! | N7: 1 | O7: 1 | P7: 1 | Q7: 0 | R7: 3 | S7: =R7/N7 -> 3 | U7: =T7/O7 -> 0 | W7: =V7/P7 -> 0 | Y7: =X7/Q7 -> #DIV/0! | Z7: 2 | AA7: 2 | AB7: 2 | AC7: 2 | AD7: 2 | AE7: =AD7/Z7 -> 1 | AG7: =AF7/AA7 -> 0 | AH7: 1 | AI7: =AH7/AB7 -> 0.5 | AK7: =AJ7/AC7 -> 0 | AL7: =B7+N7+Z7 -> 4 | AM7: =C7+O7+AA7 -> 4 | AN7: 2 | AO7: 2 | AP7: =F7+R7+AD7 -> 5 | AQ7: =AP7/AL7 -> 1.25 | AR7: =H7+T7+AF7 -> 0 | AS7: =AR7/AM7 -> 0 | AT7: =J7+V7+AH7 -> 1 | AU7: =AT7/AN7 -> 0.5 | AV7: =L7+X7+AJ7 -> 0 | AW7: =AV7/AO7 -> 0 | AX7: 45126
A8: MALAPPURAM | B8: =SUM(B3:B7) -> 13 | C8: =SUM(C3:C7) -> 7 | D8: =SUM(D3:D7) -> 3 | E8: =SUM(E3:E7) -> 4 | F8: =SUM(F3:F7) -> 11 | G8: =F8/B8 -> 0.84615385 | H8: =SUM(H3:H7) -> 0 | I8: =H8/C8 -> 0 | J8: =SUM(J3:J7) -> 4 | K8: =J8/D8 -> 1.3333333 | L8: =SUM(L3:L7) -> 6 | M8: =L8/E8 -> 1.5 | N8: =SUM(N3:N7) -> 14 | O8: =SUM(O3:O7) -> 10 | P8: =SUM(P3:P7) -> 10 | Q8: =SUM(Q3:Q7) -> 8 | R8: =SUM(R3:R7) -> 37 | S8: =R8/N8 -> 2.6428571 | T8: =SUM(T3:T7) -> 4 | U8: =T8/O8 -> 0.4 | V8: =SUM(V3:V7) -> 2 | W8: =V8/P8 -> 0.2 | X8: =SUM(X3:X7) -> 3 | Y8: =X8/Q8 -> 0.375 | Z8: =SUM(Z3:Z7) -> 18 | AA8: =SUM(AA3:AA7) -> 12 | AB8: =SUM(AB3:AB7) -> 32 | AC8: =SUM(AC3:AC7) -> 26 | AD8: =SUM(AD3:AD7) -> 56 | AE8: =AD8/Z8 -> 3.1111111 | AF8: =SUM(AF3:AF7) -> 4 | AG8: =AF8/AA8 -> 0.33333333 | AH8: =SUM(AH3:AH7) -> 22 | AI8: =AH8/AB8 -> 0.6875 | AJ8: =SUM(AJ3:AJ7) -> 17 | AK8: =AJ8/AC8 -> 0.65384615 | AL8: =SUM(AL3:AL7) -> 45 | AM8: =SUM(AM3:AM7) -> 29 | AN8: =SUM(AN3:AN7) -> 39 | AO8: =SUM(AO3:AO7) -> 33 | AP8: =SUM(AP3:AP7) -> 104 | AQ8: =AP8-AL8 -> 59 | AR8: =SUM(AR3:AR7) -> 8 | AS8: =AR8-AM8 -> -21 | AT8: =SUM(AT3:AT7) -> 28 | AU8: =AT8/AN8 -> 0.71794872 | AV8: =SUM(AV3:AV7) -> 26 | AW8: =AV8/AO8 -> 0.78787879
A9: SANEESH | B9: 3 | C9: 1 | D9: 1 | E9: 1 | F9: 4 | G9: =F9/B9 -> 1.3333333 | H9: 0 | I9: =H9/C9 -> 0 | K9: =J9/D9 -> 0 | M9: =L9/E9 -> 0 | N9: 3 | O9: 2 | P9: 3 | Q9: 2 | R9: 7 | S9: =R9/N9 -> 2.3333333 | T9: 2 | U9: =T9/O9 -> 1 | W9: =V9/P9 -> 0 | Y9: =X9/Q9 -> 0 | Z9: 10 | AA9: 2 | AB9: 10 | AC9: 8 | AD9: 21 | AE9: =AD9/Z9 -> 2.1 | AG9: =AF9/AA9 -> 0 | AH9: 10 | AI9: =AH9/AB9 -> 1 | AJ9: 8 | AK9: =AJ9/AC9 -> 1 | AL9: =B9+N9+Z9 -> 16 | AM9: =C9+O9+AA9 -> 5 | AN9: 10 | AO9: 9 | AP9: =F9+R9+AD9 -> 32 | AQ9: =AP9/AL9 -> 2 | AR9: =H9+T9+AF9 -> 2 | AS9: =AR9/AM9 -> 0.4 | AT9: =J9+V9+AH9 -> 10 | AU9: =AT9/AN9 -> 1 | AV9: =L9+X9+AJ9 -> 8 | AW9: =AV9/AO9 -> 0.88888889 | AX9: 45134
A10: EDAPPAL | B10: 2 | C10: 1 | D10: 1 | E10: 1 | F10: 1 | G10: =F10/B10 -> 0.5 | H10: 0 | I10: =H10/C10 -> 0 | K10: =J10/D10 -> 0 | L10: 2 | M10: =L10/E10 -> 2 | N10: 3 | O10: 2 | P10: 3 | Q10: 2 | R10: 7 | S10: =R10/N10 -> 2.3333333 | T10: 1 | U10: =T10/O10 -> 0.5 | V10: 1 | W10: =V10/P10 -> 0.33333333 | Y10: =X10/Q10 -> 0 | Z10: 8 | AA10: 2 | AB10: 8 | AC10: 6 | AD10: 6 | AE10: =AD10/Z10 -> 0.75 | AF10: 2 | AG10: =AF10/AA10 -> 1 | AH10: 3 | AI10: =AH10/AB10 -> 0.375 | AJ10: 3 | AK10: =AJ10/AC10 -> 0.5 | AL10: =B10+N10+Z10 -> 13 | AM10: =C10+O10+AA10 -> 5 | AN10: 9 | AO10: 7 | AP10: =F10+R10+AD10 -> 14 | AQ10: =AP10/AL10 -> 1.0769231 | AR10: =H10+T10+AF10 -> 3 | AS10: =AR10/AM10 -> 0.6 | AT10: =J10+V10+AH10 -> 4 | AU10: =AT10/AN10 -> 0.44444444 | AV10: =L10+X10+AJ10 -> 5 | AW10: =AV10/AO10 -> 0.71428571 | AX10: 45129
A11: SUMESH | B11: 2 | C11: 1 | D11: 1 | E11: 1 | F11: 1 | G11: =F11/B11 -> 0.5 | H11: 0 | I11: =H11/C11 -> 0 | J11: 1 | K11: =J11/D11 -> 1 | M11: =L11/E11 -> 0 | N11: 2 | O11: 1 | P11: 1 | Q11: 1 | R11: 2 | S11: =R11/N11 -> 1 | U11: =T11/O11 -> 0 | W11: =V11/P11 -> 0 | Y11: =X11/Q11 -> 0 | Z11: 4 | AA11: 2 | AB11: 4 | AC11: 3 | AD11: 6 | AE11: =AD11/Z11 -> 1.5 | AG11: =AF11/AA11 -> 0 | AH11: 1 | AI11: =AH11/AB11 -> 0.25 | AJ11: 1 | AK11: =AJ11/AC11 -> 0.33333333 | AL11: =B11+N11+Z11 -> 8 | AM11: =C11+O11+AA11 -> 4 | AN11: 5 | AO11: 4 | AP11: =F11+R11+AD11 -> 9 | AQ11: =AP11/AL11 -> 1.125 | AR11: =H11+T11+AF11 -> 0 | AS11: =AR11/AM11 -> 0 | AT11: =J11+V11+AH11 -> 2 | AU11: =AT11/AN11 -> 0.4 | AV11: =L11+X11+AJ11 -> 1 | AW11: =AV11/AO11 -> 0.25 | AX11: 45132
A12: KOTTAKKAL | B12: =SUM(B9:B11) -> 7 | C12: =SUM(C9:C11) -> 3 | D12: =SUM(D9:D11) -> 3 | E12: =SUM(E9:E11) -> 3 | F12: =SUM(F9:F11) -> 6 | G12: =F12/B12 -> 0.85714286 | H12: =SUM(H9:H11) -> 0 | I12: =H12/C12 -> 0 | J12: =SUM(J9:J11) -> 1 | K12: =J12/D12 -> 0.33333333 | L12: =SUM(L9:L11) -> 2 | M12: =L12/E12 -> 0.66666667 | N12: =SUM(N9:N11) -> 8 | O12: =SUM(O9:O11) -> 5 | P12: =SUM(P9:P11) -> 7 | Q12: =SUM(Q9:Q11) -> 5 | R12: =SUM(R9:R11) -> 16 | S12: =R12/N12 -> 2 | T12: =SUM(T9:T11) -> 3 | U12: =T12/O12 -> 0.6 | V12: =SUM(V9:V11) -> 1 | W12: =V12/P12 -> 0.14285714 | X12: =SUM(X9:X11) -> 0 | Y12: =X12/Q12 -> 0 | Z12: =SUM(Z9:Z11) -> 22 | AA12: =SUM(AA9:AA11) -> 6 | AB12: =SUM(AB9:AB11) -> 22 | AC12: =SUM(AC9:AC11) -> 17 | AD12: =SUM(AD9:AD11) -> 33 | AE12: =AD12/Z12 -> 1.5 | AF12: =SUM(AF9:AF11) -> 2 | AG12: =AF12/AA12 -> 0.33333333 | AH12: =SUM(AH9:AH11) -> 14 | AI12: =AH12/AB12 -> 0.63636364 | AJ12: =SUM(AJ9:AJ11) -> 12 | AK12: =AJ12/AC12 -> 0.70588235 | AL12: =SUM(AL9:AL11) -> 37 | AM12: =SUM(AM9:AM11) -> 14 | AN12: =SUM(AN9:AN11) -> 24 | AO12: =SUM(AO9:AO11) -> 20 | AP12: =SUM(AP9:AP11) -> 55 | AQ12: =AP12-AL12 -> 18 | AR12: =SUM(AR9:AR11) -> 5 | AS12: =AR12-AM12 -> -9 | AT12: =SUM(AT9:AT11) -> 16 | AU12: =AT12-AN12 -> -8 | AV12: =SUM(AV9:AV11) -> 14 | AW12: =AV12/AO12 -> 0.7
A13: TOTAL | B13: =SUM(B12+B8) -> 20 | C13: =SUM(C12+C8) -> 10 | D13: =SUM(D12+D8) -> 6 | E13: =SUM(E12+E8) -> 7 | F13: =SUM(F12+F8) -> 17 | G13: =F13/B13 -> 0.85 | H13: =SUM(H12+H8) -> 0 | I13: =H13/C13 -> 0 | J13: =SUM(J12+J8) -> 5 | K13: =J13/D13 -> 0.83333333 | L13: =SUM(L12+L8) -> 8 | M13: =L13/E13 -> 1.1428571 | N13: =SUM(N12+N8) -> 22 | O13: =SUM(O12+O8) -> 15 | P13: =SUM(P12+P8) -> 17 | Q13: =SUM(Q12+Q8) -> 13 | R13: =SUM(R12+R8) -> 53 | S13: =R13/N13 -> 2.4090909 | T13: =SUM(T12+T8) -> 7 | U13: =T13/O13 -> 0.46666667 | V13: =SUM(V12+V8) -> 3 | W13: =V13/P13 -> 0.17647059 | X13: =SUM(X12+X8) -> 3 | Y13: =X13/Q13 -> 0.23076923 | Z13: =SUM(Z12+Z8) -> 40 | AA13: =SUM(AA12+AA8) -> 18 | AB13: =SUM(AB12+AB8) -> 54 | AC13: =SUM(AC12+AC8) -> 43 | AD13: =SUM(AD12+AD8) -> 89 | AE13: =AD13/Z13 -> 2.225 | AF13: =SUM(AF12+AF8) -> 6 | AG13: =AF13/AA13 -> 0.33333333 | AH13: =SUM(AH12+AH8) -> 36 | AI13: =AH13/AB13 -> 0.66666667 | AJ13: =SUM(AJ12+AJ8) -> 29 | AK13: =AJ13/AC13 -> 0.6744186 | AL13: =SUM(AL12+AL8) -> 82 | AM13: =SUM(AM12+AM8) -> 43 | AN13: =SUM(AN12+AN8) -> 63 | AO13: =SUM(AO12+AO8) -> 53 | AP13: =SUM(AP12+AP8) -> 159 | AQ13: =AP13-AL13 -> 77 | AR13: =SUM(AR12+AR8) -> 13 | AS13: =AR13-AM13 -> -30 | AT13: =SUM(AT12+AT8) -> 44 | AU13: =AT13-AN13 -> -19 | AV13: =SUM(AV12+AV8) -> 40 | AW13: =AV13/AO13 -> 0.75471698

Sheet Compare
A1: Month Comparison
A2: TL/ASM | B2: ACH TILL 1-10(JUNE) | E2: ACH TILL 1-10(JULY) | H2: July Commitment
B3: BKGS | C3: IN STOCK | D3: RETAIL | E3: BKGS | F3: IN STOCK | G3: RETAIL | H3: RETAIL
A4: RISHAD | B4: 5 | C4: 4 | D4: 0 | E4: 5 | F4: 0 | G4: 1 | H4: 12
A5: JISHNU | B5: 6 | C5: 4 | D5: 2 | E5: 4 | F5: 0 | G5: 2 | H5: 12
A6: JIJEESH | B6: 2 | C6: 0 | D6: 0 | E6: 2 | F6: 0 | G6: 1 | H6: 5
A7: JYOTHISH | B7: 2 | C7: 0 | D7: 0 | E7: 0 | F7: 0 | G7: 0 | H7: 8
A8: KHAYYOOM | B8: - | C8: - | D8: - | E8: 0 | F8: 0 | G8: 0 | H8: 2
A9: MALAPPURAM | B9: =SUM(B4:B7) -> 15 | C9: =SUM(C4:C7) -> 8 | D9: =SUM(D4:D7) -> 2 | E9: =SUM(E4:E8) -> 11 | F9: =SUM(F4:F8) -> 0 | G9: =SUM(G4:G8) -> 4 | H9: =SUM(H4:H8) -> 39
A10: SANEESH | B10: 5 | C10: 1 | D10: 1 | E10: 4 | F10: 0 | G10: 0 | H10: 10
A11: SANDEEP | B11: 3 | C11: 0 | D11: 0 | E11: 1 | F11: 0 | G11: 0 | H11: 9
A12: SUMESH | B12: 2 | C12: 1 | D12: 0 | E12: 1 | F12: 0 | G12: 1 | H12: 5
A13: KOTTAKKAL | B13: =SUM(B10:B12) -> 10 | C13: =SUM(C10:C12) -> 2 | D13: =SUM(D10:D12) -> 1 | E13: =SUM(E10:E12) -> 6 | F13: =SUM(F10:F12) -> 0 | G13: =SUM(G10:G12) -> 1 | H13: =SUM(H10:H12) -> 24
A14: TOTAL | B14: =SUM(B13+B9) -> 25 | C14: =SUM(C13+C9) -> 10 | D14: =SUM(D13+D9) -> 3 | E14: =SUM(E13+E9) -> 17 | F14: =SUM(F13+F9) -> 0 | G14: =SUM(G13+G9) -> 5 | H14: =SUM(H13+H9) -> 63

Sheet RTO Wise Jul-23
A1: RTO WISE REPORT TILL 1--10 | I1: RTO WISE REPORT TILL 18--31
A2: RTO | B2: TOTAL | C2: CLASSIC | D2: % | E2: OTHERS | F2: % | I2: RTO | J2: TOTAL | K2: CLASSIC | L2: % | M2: OTHERS | N2: %
A3: MALAPPURAM | B3: 3 | C3: 1 | D3: =C3/B3 -> 0.33333333 | E3: =B3-C3 -> 2 | F3: =E3/B3 -> 0.66666667 | I3: MALAPPURAM | J3: 12 | K3: 6 | L3: =K3/J3 -> 0.5 | M3: =J3-K3 -> 6 | N3: =M3/J3 -> 0.5
A4: KONDOTTY | B4: 3 | C4: 1 | D4: =C4/B4 -> 0.33333333 | E4: =B4-C4 -> 2 | F4: =E4/B4 -> 0.66666667 | I4: KONDOTTY | J4: 8 | K4: 4 | L4: =K4/J4 -> 0.5 | M4: =J4-K4 -> 4 | N4: =M4/J4 -> 0.5
A5: NILAMBUR | B5: 2 | C5: 1 | D5: =C5/B5 -> 0.5 | E5: =B5-C5 -> 1 | F5: =E5/B5 -> 0.5 | I5: NILAMBUR | J5: 5 | K5: 4 | L5: =K5/J5 -> 0.8 | M5: =J5-K5 -> 1 | N5: =M5/J5 -> 0.2
A6: PERINTHALMANNA | B6: 8 | C6: 3 | D6: =C6/B6 -> 0.375 | E6: =B6-C6 -> 5 | F6: =E6/B6 -> 0.625 | I6: PERINTHALMANNA | J6: 4 | K6: 0 | L6: =K6/J6 -> 0 | M6: =J6-K6 -> 4 | N6: =M6/J6 -> 1
A7: THIRUR | B7: 3 | C7: 1 | D7: =C7/B7 -> 0.33333333 | E7: =B7-C7 -> 2 | F7: =E7/B7 -> 0.66666667 | I7: THIRUR | J7: 12 | K7: 5 | L7: =K7/J7 -> 0.41666667 | M7: =J7-K7 -> 7 | N7: =M7/J7 -> 0.58333333
A8: THIRURANGADI | B8: 4 | C8: 0 | D8: =C8/B8 -> 0 | E8: =B8-C8 -> 4 | F8: =E8/B8 -> 1 | I8: THIRURANGADI | J8: 20 | K8: 4 | L8: =K8/J8 -> 0.2 | M8: =J8-K8 -> 16 | N8: =M8/J8 -> 0.8
A9: PONNANI | B9: 2 | C9: 1 | D9: =C9/B9 -> 0.5 | E9: =B9-C9 -> 1 | F9: =E9/B9 -> 0.5 | I9: PONNANI | J9: 6 | K9: 3 | L9: =K9/J9 -> 0.5 | M9: =J9-K9 -> 3 | N9: =M9/J9 -> 0.5
A10: OTHER | C10: 1 | I10: OTHER | K10: 4
A11: TOTAL | B11: =SUM(B3:B9) -> 25 | C11: =SUM(C3:C9) -> 8 | D11: =C11/B11 -> 0.32 | E11: =B11-C11 -> 17 | F11: =E11/B11 -> 0.68 | I11: TOTAL | J11: =SUM(J3:J10) -> 67 | K11: =SUM(K3:K9) -> 26 | L11: =K11/J11 -> 0.3880597 | M11: =J11-K11 -> 41 | N11: =M11/J11 -> 0.6119403
A13: RTO WISE REPORT TILL 11--17 | I13: RTO WISE REPORT JULY-2023
A14: RTO | B14: TOTAL | C14: CLASSIC | D14: % | E14: OTHERS | F14: % | I14: RTO | J14: TOTAL | K14: CLASSIC | L14: % | M14: OTHERS | N14: %
A15: MALAPPURAM | B15: 4 | C15: 2 | D15: =C15/B15 -> 0.5 | E15: =B15-C15 -> 2 | F15: =E15/B15 -> 0.5 | I15: MALAPPURAM | J15: =B3+B15+J3 -> 19 | K15: =C3+C15+K3 -> 9 | L15: =K15/J15 -> 0.47368421 | M15: =J15-K15 -> 10 | N15: =M15/J15 -> 0.52631579
A16: KONDOTTY | B16: 2 | C16: 1 | D16: =C16/B16 -> 0.5 | E16: =B16-C16 -> 1 | F16: =E16/B16 -> 0.5 | I16: KONDOTTY | J16: =B4+B16+J4 -> 13 | K16: =C4+C16+K4 -> 6 | L16: =K16/J16 -> 0.46153846 | M16: =J16-K16 -> 7 | N16: =M16/J16 -> 0.53846154
A17: NILAMBUR | B17: 2 | C17: 0 | D17: =C17/B17 -> 0 | E17: =B17-C17 -> 2 | F17: =E17/B17 -> 1 | I17: NILAMBUR | J17: =B5+B17+J5 -> 9 | K17: =C5+C17+K5 -> 5 | L17: =K17/J17 -> 0.55555556 | M17: =J17-K17 -> 4 | N17: =M17/J17 -> 0.44444444
A18: PERINTHALMANNA | B18: 0 | C18: 0 | D18: =C18/B18 -> #DIV/0! | E18: =B18-C18 -> 0 | F18: =E18/B18 -> #DIV/0! | I18: PERINTHALMANNA | J18: =B6+B18+J6 -> 12 | K18: =C6+C18+K6 -> 3 | L18: =K18/J18 -> 0.25 | M18: =J18-K18 -> 9 | N18: =M18/J18 -> 0.75
A19: THIRUR | B19: 3 | C19: 0 | D19: =C19/B19 -> 0 | E19: =B19-C19 -> 3 | F19: =E19/B19 -> 1 | I19: THIRUR | J19: =B7+B19+J7 -> 18 | K19: =C7+C19+K7 -> 6 | L19: =K19/J19 -> 0.33333333 | M19: =J19-K19 -> 12 | N19: =M19/J19 -> 0.66666667
A20: THIRURANGADI | B20: 1 | C20: 0 | D20: =C20/B20 -> 0 | E20: =B20-C20 -> 1 | F20: =E20/B20 -> 1 | I20: THIRURANGADI | J20: =B8+B20+J8 -> 25 | K20: =C8+C20+K8 -> 4 | L20: =K20/J20 -> 0.16 | M20: =J20-K20 -> 21 | N20: =M20/J20 -> 0.84
A21: PONNANI | B21: 2 | C21: 0 | D21: =C21/B21 -> 0 | E21: =B21-C21 -> 2 | F21: =E21/B21 -> 1 | I21: PONNANI | J21: =B9+B21+J9 -> 10 | K21: =C9+C21+K9 -> 4 | L21: =K21/J21 -> 0.4 | M21: =J21-K21 -> 6 | N21: =M21/J21 -> 0.6
A22: OTHER | I22: OTHER | J22: =B10+B22+J10 -> 0 | K22: =C10+C22+K10 -> 5 | M22: =E10+E22+M10 -> 0
A23: TOTAL | B23: =SUM(B15:B22) -> 14 | C23: =SUM(C15:C22) -> 3 | D23: =C23/B23 -> 0.21428571 | E23: =B23-C23 -> 11 | F23: =E23/B23 -> 0.78571429 | I23: TOTAL | J23: =SUM(J15:J21) -> 106 | K23: =SUM(K15:K21) -> 37 | L23: =K23/J23 -> 0.3490566 | M23: =J23-K23 -> 69 | N23: =M23/J23 -> 0.6509434

Sheet Wholesale Vs Retail
A1: HMIL TARGET JUNE 2023
A2: REGION | B2: WHOLESALE | E2: RETAIL
B3: TGT | C3: ACH | D3: % | E3: TGT | F3: ACH | G3: %
A4: MPM | B4: 35 | C4: 35 | D4: =C4/B4 -> 1 | E4: 30 | F4: 28 | G4: =F4/E4 -> 0.93333333
A5: KKL | B5: 10 | C5: 10 | D5: =C5/B5 -> 1 | E5: 10 | F5: 8 | G5: =F5/E5 -> 0.8
A6: WYD | B6: 35 | C6: 35 | D6: =C6/B6 -> 1 | E6: 35 | F6: 23 | G6: =F6/E6 -> 0.65714286
A7: TOTAL | B7: =SUM(B4:B6) -> 80 | C7: =SUM(C4:C6) -> 80 | D7: =C7/B7 -> 1 | E7: =SUM(E4:E6) -> 75 | F7: =SUM(F4:F6) -> 59 | G7: =F7/E7 -> 0.78666667
A9: HMIL TARGET JULY 2023
A10: REGION | B10: WHOLESALE | E10: RETAIL
B11: TGT | C11: ACH | D11: % | E11: TGT | F11: ACH | G11: %
A12: MPM | B12: 40 | C12: 45 | D12: =C12/B12 -> 1.125 | E12: 35 | F12: 36 | G12: =F12/E12 -> 1.0285714
A13: KKL | B13: 10 | C13: 4 | D13: =C13/B13 -> 0.4 | E13: 15 | F13: 14 | G13: =F13/E13 -> 0.93333333
A14: WYD | B14: 35 | C14: 36 | D14: =C14/B14 -> 1.0285714 | E14: 30 | F14: 30 | G14: =F14/E14 -> 1
A15: TOTAL | B15: =SUM(B12:B14) -> 85 | C15: =SUM(C12:C14) -> 85 | D15: =C15/B15 -> 1 | E15: =SUM(E12:E14) -> 80 | F15: =SUM(F12:F14) -> 80 | G15: =F15/E15 -> 1
A17: HMIL TARGET AUG 2023
A18: REGION | B18: WHOLESALE | E18: RETAIL
B19: TGT | C19: ACH | D19: % | E19: TGT | F19: ACH | G19: %
A20: MPM | D20: =C20/B20 -> #DIV/0! | E20: 50 | F20: 9 | G20: =F20/E20 -> 0.18
A21: KKL | D21: =C21/B21 -> #DIV/0! | E21: 25 | F21: 4 | G21: =F21/E21 -> 0.16
A22: WYD | D22: =C22/B22 -> #DIV/0! | E22: 50 | F22: 17 | G22: =F22/E22 -> 0.34
A23: TOTAL | B23: =SUM(B20:B22) -> 0 | C23: =SUM(C20:C22) -> 0 | D23: =C23/B23 -> #DIV/0! | E23: =SUM(E20:E22) -> 125 | F23: =SUM(F20:F22) -> 30 | G23: =F23/E23 -> 0.24

Sheet Cmt Vs Tgt Jun-23
A1: TL/ASM | B1: 1-10 Commitment | E1: ACH TILL 1-10 | K1: 11-17 Commitment | M1: ACH TILL 11-17 | Q1: 18-27 Commitment | T1: ACH 18-27 | Z1: ACH TILL 30-06-2023 | AC1: ACTUAL | AI1: Last Booking Date
B2: BKGS | C2: IN STOCK | D2: RETAIL | E2: BKGS | F2: % | G2: IN STOCK | H2: % | I2: RETAIL | J2: % | K2: BKGS | L2: RETAIL | M2: BKGS | N2: % | O2: RETAIL | P2: % | Q2: BKGS | R2: IN STOCK | S2: RETAIL | T2: BKGS | U2: % | V2: IN STOCK | W2: % | X2: RETAIL | Y2: % | Z2: BKGS | AA2: IN STOCK | AB2: RETAIL | AC2: TDY | AD2: BKGS | AE2: RETAIL | AF2: % | AG2: TP | AH2: %
A3: RISHAD | B3: 4 | C3: 2 | D3: 2 | E3: 5 | F3: =E3/B3 -> 1.25 | G3: 4 | H3: =G3/C3 -> 2 | I3: 0 | J3: =I3/D3 -> 0 | K3: 3 | L3: 4 | M3: 4 | N3: =M3/K3 -> 1.3333333 | O3: 2 | P3: =O3/L3 -> 0.5 | Q3: 4 | R3: 3 | S3: 5 | T3: 4 | U3: =T3/Q3 -> 1 | V3: 1 | W3: =V3/R3 -> 0.33333333 | X3: 6 | Y3: =X3/S3 -> 1.2 | Z3: 0 | AA3: 0 | AB3: 1 | AD3: 13 | AE3: 9 | AF3: =AE3/AD3 -> 0.69230769 | AG3: 8 | AH3: =AG3/AE3 -> 0.88888889 | AI3: 45104
A4: JISHNU | B4: 4 | C4: 2 | D4: 2 | E4: 6 | F4: =E4/B4 -> 1.5 | G4: 4 | H4: =G4/C4 -> 2 | I4: 2 | J4: =I4/D4 -> 1 | K4: 3 | L4: 2 | M4: 3 | N4: =M4/K4 -> 1 | O4: 2 | P4: =O4/L4 -> 1 | Q4: 4 | R4: 3 | S4: 4 | T4: 5 | U4: =T4/Q4 -> 1.25 | V4: 2 | W4: =V4/R4 -> 0.66666667 | X4: 4 | Y4: =X4/S4 -> 1 | Z4: 0 | AA4: 0 | AB4: 3 | AD4: 15 | AE4: 11 | AF4: =AE4/AD4 -> 0.73333333 | AG4: 8 | AH4: =AG4/AE4 -> 0.72727273 | AI4: 45102
A5: JIJEESH | B5: 2 | C5: 2 | D5: 2 | E5: 2 | F5: =E5/B5 -> 1 | G5: 0 | H5: =G5/C5 -> 0 | I5: 0 | J5: =I5/D5 -> 0 | K5: 3 | L5: 2 | M5: 0 | N5: =M5/K5 -> 0 | O5: 0 | P5: =O5/L5 -> 0 | Q5: 5 | R5: 2 | S5: 4 | T5: 1 | U5: =T5/Q5 -> 0.2 | V5: 0 | W5: =V5/R5 -> 0 | X5: 2 | Y5: =X5/S5 -> 0.5 | Z5: 0 | AA5: 0 | AB5: 0 | AD5: 3 | AE5: 2 | AF5: =AE5/AD5 -> 0.66666667 | AG5: 3 | AH5: =AG5/AE5 -> 1.5 | AI5: 45096
A6: JYOTHISH | B6: 2 | C6: 2 | D6: 2 | E6: 2 | F6: =E6/B6 -> 1 | G6: 0 | H6: =G6/C6 -> 0 | I6: 0 | J6: =I6/D6 -> 0 | K6: 2 | L6: 1 | M6: 2 | N6: =M6/K6 -> 1 | O6: 0 | P6: =O6/L6 -> 0 | Q6: 3 | R6: 3 | S6: 3 | T6: 2 | U6: =T6/Q6 -> 0.66666667 | V6: 1 | W6: =V6/R6 -> 0.33333333 | X6: 0 | Y6: =X6/S6 -> 0 | Z6: 0 | AA6: 0 | AB6: 1 | AD6: 7 | AE6: 1 | AF6: =AE6/AD6 -> 0.14285714 | AG6: 1 | AH6: =AG6/AE6 -> 1 | AI6: 45104
A7: MALAPPURAM | B7: =SUM(B3:B6) -> 12 | C7: =SUM(C3:C6) -> 8 | D7: =SUM(D3:D6) -> 8 | E7: =SUM(E3:E6) -> 15 | F7: =E7/B7 -> 1.25 | G7: =SUM(G3:G6) -> 8 | H7: =G7/C7 -> 1 | I7: =SUM(I3:I6) -> 2 | J7: =I7/D7 -> 0.25 | K7: =SUM(K3:K6) -> 11 | L7: =SUM(L3:L6) -> 9 | M7: =SUM(M3:M6) -> 9 | N7: =M7/K7 -> 0.81818182 | O7: =SUM(O3:O6) -> 4 | P7: =O7/L7 -> 0.44444444 | Q7: =SUM(Q3:Q6) -> 16 | R7: =SUM(R3:R6) -> 11 | S7: =SUM(S3:S6) -> 16 | T7: =SUM(T3:T6) -> 12 | U7: =T7/Q7 -> 0.75 | V7: =SUM(V3:V6) -> 4 | W7: =V7/R7 -> 0.36363636 | X7: =SUM(X3:X6) -> 12 | Y7: =X7/S7 -> 0.75 | Z7: =SUM(Z3:Z6) -> 0 | AA7: =SUM(AA3:AA6) -> 0 | AB7: =SUM(AB3:AB6) -> 5 | AC7: =SUM(AC3:AC6) -> 0 | AD7: =SUM(AD3:AD6) -> 38 | AE7: =SUM(AE3:AE6) -> 23 | AF7: =AE7/AD7 -> 0.60526316 | AG7: =SUM(AG3:AG6) -> 20 | AH7: =AG7/AE7 -> 0.86956522
A8: SANEESH | B8: 4 | C8: 2 | D8: 2 | E8: 5 | F8: =E8/B8 -> 1.25 | G8: 1 | H8: =G8/C8 -> 0.5 | I8: 1 | J8: =I8/D8 -> 0.5 | K8: 3 | L8: 3 | M8: 2 | N8: =M8/K8 -> 0.66666667 | O8: 2 | P8: =O8/L8 -> 0.66666667 | Q8: 5 | R8: 4 | S8: 5 | T8: 2 | U8: =T8/Q8 -> 0.4 | V8: 1 | W8: =V8/R8 -> 0.25 | X8: 3 | Y8: =X8/S8 -> 0.6 | Z8: 1 | AA8: 0 | AB8: 2 | AD8: 10 | AE8: 8 | AF8: =AE8/AD8 -> 0.8 | AG8: 10 | AH8: =AG8/AE8 -> 1.25 | AI8: 45105
A9: SANDEEP | B9: 4 | C9: 2 | D9: 2 | E9: 3 | F9: =E9/B9 -> 0.75 | G9: 0 | H9: =G9/C9 -> 0 | I9: 0 | J9: =I9/D9 -> 0 | K9: 4 | L9: 3 | M9: 5 | N9: =M9/K9 -> 1.25 | O9: 0 | P9: =O9/L9 -> 0 | Q9: 7 | R9: 3 | S9: 7 | T9: 1 | U9: =T9/Q9 -> 0.14285714 | V9: 0 | W9: =V9/R9 -> 0 | X9: 1 | Y9: =X9/S9 -> 0.14285714 | Z9: 0 | AA9: 0 | AB9: 3 | AD9: 9 | AE9: 4 | AF9: =AE9/AD9 -> 0.44444444 | AG9: 2 | AH9: =AG9/AE9 -> 0.5 | AI9: 45099
A10: SUMESH | B10: 1 | C10: 1 | D10: 1 | E10: 2 | F10: =E10/B10 -> 2 | G10: 1 | H10: =G10/C10 -> 1 | I10: 0 | J10: =I10/D10 -> 0 | K10: 1 | L10: 1 | M10: 0 | N10: =M10/K10 -> 0 | O10: 1 | P10: =O10/L10 -> 1 | Q10: 4 | R10: 3 | S10: 3 | T10: 1 | U10: =T10/Q10 -> 0.25 | V10: 0 | W10: =V10/R10 -> 0 | X10: 0 | Y10: =X10/S10 -> 0 | Z10: 0 | AA10: 0 | AB10: 0 | AD10: 3 | AE10: 1 | AF10: =AE10/AD10 -> 0.33333333 | AG10: 1 | AH10: =AG10/AE10 -> 1 | AI10: 45103
A11: KOTTAKKAL | B11: =SUM(B8:B10) -> 9 | C11: =SUM(C8:C10) -> 5 | D11: =SUM(D8:D10) -> 5 | E11: =SUM(E8:E10) -> 10 | F11: =E11/B11 -> 1.1111111 | G11: =SUM(G8:G10) -> 2 | H11: =G11/C11 -> 0.4 | I11: =SUM(I8:I10) -> 1 | J11: =I11/D11 -> 0.2 | K11: =SUM(K8:K10) -> 8 | L11: =SUM(L8:L10) -> 7 | M11: =SUM(M8:M10) -> 7 | N11: =M11/K11 -> 0.875 | O11: =SUM(O8:O10) -> 3 | P11: =O11/L11 -> 0.42857143 | Q11: =SUM(Q8:Q10) -> 16 | R11: =SUM(R8:R10) -> 10 | S11: =SUM(S8:S10) -> 15 | T11: =SUM(T8:T10) -> 4 | U11: =T11/Q11 -> 0.25 | V11: =SUM(V8:V10) -> 1 | W11: =V11/R11 -> 0.1 | X11: =SUM(X8:X10) -> 4 | Y11: =X11/S11 -> 0.26666667 | Z11: =SUM(Z8:Z10) -> 1 | AA11: =SUM(AA8:AA10) -> 0 | AB11: =SUM(AB8:AB10) -> 5 | AC11: =SUM(AC8:AC10) -> 0 | AD11: =SUM(AD8:AD10) -> 22 | AE11: =SUM(AE8:AE10) -> 13 | AF11: =AE11/AD11 -> 0.59090909 | AG11: =SUM(AG8:AG10) -> 13 | AH11: =AG11/AE11 -> 1
A12: TOTAL | B12: =SUM(B11+B7) -> 21 | C12: =SUM(C11+C7) -> 13 | D12: =SUM(D11+D7) -> 13 | E12: =SUM(E11+E7) -> 25 | F12: =E12/B12 -> 1.1904762 | G12: =SUM(G11+G7) -> 10 | H12: =G12/C12 -> 0.76923077 | I12: =SUM(I11+I7) -> 3 | J12: =I12/D12 -> 0.23076923 | K12: =SUM(K11+K7) -> 19 | L12: =SUM(L11+L7) -> 16 | M12: =SUM(M11+M7) -> 16 | N12: =M12/K12 -> 0.84210526 | O12: =SUM(O11+O7) -> 7 | P12: =O12/L12 -> 0.4375 | Q12: =SUM(Q11+Q7) -> 32 | R12: =SUM(R11+R7) -> 21 | S12: =SUM(S11+S7) -> 31 | T12: =SUM(T11+T7) -> 16 | U12: =T12/Q12 -> 0.5 | V12: =SUM(V11+V7) -> 5 | W12: =V12/R12 -> 0.23809524 | X12: =SUM(X11+X7) -> 16 | Y12: =X12/S12 -> 0.51612903 | Z12: =SUM(Z11+Z7) -> 1 | AA12: =SUM(AA11+AA7) -> 0 | AB12: =SUM(AB11+AB7) -> 10 | AC12: =SUM(AC11+AC7) -> 0 | AD12: =SUM(AD11+AD7) -> 60 | AE12: =SUM(AE11+AE7) -> 36 | AF12: =AE12/AD12 -> 0.6 | AG12: =SUM(AG11+AG7) -> 33 | AH12: =AG12/AE12 -> 0.91666667

Sheet RTO Wise Jun-23
A1: RTO WISE REPORT - 2024
B2: JAN | G2: FEB | L2: MAR | Q2: APR | V2: MAY | AA2: JUN | AF2: JUL | AK2: AUG | AP2: SEP | AU2: OCT | AZ2: NOV | BE2: DEC | BJ2: 2024
A3: RTO | B3: TOTAL | C3: CLASSIC | D3: % | E3: OTHERS | F3: % | G3: TOTAL | H3: CLASSIC | I3: % | J3: OTHERS | K3: % | L3: TOTAL | M3: CLASSIC | N3: % | O3: OTHERS | P3: % | Q3: TOTAL | R3: CLASSIC | S3: % | T3: OTHERS | U3: % | V3: TOTAL | W3: CLASSIC | X3: % | Y3: OTHERS | Z3: % | AA3: TOTAL | AB3: CLASSIC | AC3: % | AD3: OTHERS | AE3: % | AF3: TOTAL | AG3: CLASSIC | AH3: % | AI3: OTHERS | AJ3: % | AK3: TOTAL | AL3: CLASSIC | AM3: % | AN3: OTHERS | AO3: % | AP3: TOTAL | AQ3: CLASSIC | AR3: % | AS3: OTHERS | AT3: % | AU3: TOTAL | AV3: CLASSIC | AW3: % | AX3: OTHERS | AY3: % | AZ3: TOTAL | BA3: CLASSIC | BB3: % | BC3: OTHERS | BD3: % | BE3: TOTAL | BF3: CLASSIC | BG3: % | BH3: OTHERS | BI3: % | BJ3: TOTAL | BK3: CLASSIC | BL3: % | BM3: OTHERS | BN3: %
A4: MALAPPURAM | B4: 23 | C4: 9 | D4: =C4/B4 -> 0.39130435 | E4: =B4-C4 -> 14 | F4: =E4/B4 -> 0.60869565 | G4: 19 | H4: 8 | I4: =H4/G4 -> 0.42105263 | J4: =G4-H4 -> 11 | K4: =J4/G4 -> 0.57894737 | L4: 21 | M4: 6 | N4: =M4/L4 -> 0.28571429 | O4: =L4-M4 -> 15 | P4: =O4/L4 -> 0.71428571 | Q4: 22 | R4: 10 | S4: =R4/Q4 -> 0.45454545 | T4: =Q4-R4 -> 12 | U4: =T4/Q4 -> 0.54545455 | V4: 18 | W4: 4 | X4: =W4/V4 -> 0.22222222 | Y4: =V4-W4 -> 14 | Z4: =Y4/V4 -> 0.77777778 | AA4: 24 | AB4: 7 | AC4: =AB4/AA4 -> 0.29166667 | AD4: =AA4-AB4 -> 17 | AE4: =AD4/AA4 -> 0.70833333 | AF4: 24 | AG4: 3 | AH4: =AG4/AF4 -> 0.125 | AI4: =AF4-AG4 -> 21 | AJ4: =AI4/AF4 -> 0.875 | AK4: 20 | AL4: 7 | AM4: =AL4/AK4 -> 0.35 | AN4: =AK4-AL4 -> 13 | AO4: =AN4/AK4 -> 0.65 | AP4: 18 | AQ4: 14 | AR4: =AQ4/AP4 -> 0.77777778 | AS4: =AP4-AQ4 -> 4 | AT4: =AS4/AP4 -> 0.22222222 | AU4: 10 | AV4: 3 | AW4: =AV4/AU4 -> 0.3 | AX4: =AU4-AV4 -> 7 | AY4: =AX4/AU4 -> 0.7 | BB4: =BA4/AZ4 -> #DIV/0! | BC4: =AZ4-BA4 -> 0 | BD4: =BC4/AZ4 -> #DIV/0! | BG4: =BF4/BE4 -> #DIV/0! | BH4: =BE4-BF4 -> 0 | BI4: =BH4/BE4 -> #DIV/0! | BJ4: =B4+G4+L4+Q4+V4+AA4+AF4+AK4+AP4+AU4+AZ4+BE4 -> 199 | BK4: =C4+H4+M4+R4+W4+AB4+AG4+AL4+AQ4+AV4+BA4+BF4 -> 71 | BL4: =BK4/BJ4 -> 0.35678392 | BM4: =BJ4-BK4 -> 128 | BN4: =BM4/BJ4 -> 0.64321608
A5: KONDOTTY | B5: 14 | C5: 2 | D5: =C5/B5 -> 0.14285714 | E5: =B5-C5 -> 12 | F5: =E5/B5 -> 0.85714286 | G5: 17 | H5: 1 | I5: =H5/G5 -> 0.058823529 | J5: =G5-H5 -> 16 | K5: =J5/G5 -> 0.94117647 | L5: 15 | M5: 5 | N5: =M5/L5 -> 0.33333333 | O5: =L5-M5 -> 10 | P5: =O5/L5 -> 0.66666667 | Q5: 11 | R5: 1 | S5: =R5/Q5 -> 0.090909091 | T5: =Q5-R5 -> 10 | U5: =T5/Q5 -> 0.90909091 | V5: 11 | W5: 3 | X5: =W5/V5 -> 0.27272727 | Y5: =V5-W5 -> 8 | Z5: =Y5/V5 -> 0.72727273 | AA5: 18 | AB5: 2 | AC5: =AB5/AA5 -> 0.11111111 | AD5: =AA5-AB5 -> 16 | AE5: =AD5/AA5 -> 0.88888889 | AF5: 12 | AG5: 1 | AH5: =AG5/AF5 -> 0.083333333 | AI5: =AF5-AG5 -> 11 | AJ5: =AI5/AF5 -> 0.91666667 | AK5: 10 | AL5: 2 | AM5: =AL5/AK5 -> 0.2 | AN5: =AK5-AL5 -> 8 | AO5: =AN5/AK5 -> 0.8 | AP5: 17 | AQ5: 1 | AR5: =AQ5/AP5 -> 0.058823529 | AS5: =AP5-AQ5 -> 16 | AT5: =AS5/AP5 -> 0.94117647 | AU5: 13 | AV5: 1 | AW5: =AV5/AU5 -> 0.076923077 | AX5: =AU5-AV5 -> 12 | AY5: =AX5/AU5 -> 0.92307692 | BB5: =BA5/AZ5 -> #DIV/0! | BC5: =AZ5-BA5 -> 0 | BD5: =BC5/AZ5 -> #DIV/0! | BG5: =BF5/BE5 -> #DIV/0! | BH5: =BE5-BF5 -> 0 | BI5: =BH5/BE5 -> #DIV/0! | BJ5: =B5+G5+L5+Q5+V5+AA5+AF5+AK5+AP5+AU5+AZ5+BE5 -> 138 | BK5: =C5+H5+M5+R5+W5+AB5+AG5+AL5+AQ5+AV5+BA5+BF5 -> 19 | BL5: =BK5/BJ5 -> 0.13768116 | BM5: =BJ5-BK5 -> 119 | BN5: =BM5/BJ5 -> 0.86231884
A6: NILAMBUR | B6: 16 | C6: 2 | D6: =C6/B6 -> 0.125 | E6: =B6-C6 -> 14 | F6: =E6/B6 -> 0.875 | G6: 15 | H6: 8 | I6: =H6/G6 -> 0.53333333 | J6: =G6-H6 -> 7 | K6: =J6/G6 -> 0.46666667 | L6: 15 | M6: 6 | N6: =M6/L6 -> 0.4 | O6: =L6-M6 -> 9 | P6: =O6/L6 -> 0.6 | Q6: 13 | R6: 6 | S6: =R6/Q6 -> 0.46153846 | T6: =Q6-R6 -> 7 | U6: =T6/Q6 -> 0.53846154 | V6: 15 | W6: 5 | X6: =W6/V6 -> 0.33333333 | Y6: =V6-W6 -> 10 | Z6: =Y6/V6 -> 0.66666667 | AA6: 10 | AB6: 3 | AC6: =AB6/AA6 -> 0.3 | AD6: =AA6-AB6 -> 7 | AE6: =AD6/AA6 -> 0.7 | AF6: 11 | AG6: 4 | AH6: =AG6/AF6 -> 0.36363636 | AI6: =AF6-AG6 -> 7 | AJ6: =AI6/AF6 -> 0.63636364 | AK6: 14 | AL6: 8 | AM6: =AL6/AK6 -> 0.57142857 | AN6: =AK6-AL6 -> 6 | AO6: =AN6/AK6 -> 0.42857143 | AP6: 23 | AQ6: 6 | AR6: =AQ6/AP6 -> 0.26086957 | AS6: =AP6-AQ6 -> 17 | AT6: =AS6/AP6 -> 0.73913043 | AU6: 10 | AV6: 1 | AW6: =AV6/AU6 -> 0.1 | AX6: =AU6-AV6 -> 9 | AY6: =AX6/AU6 -> 0.9 | BB6: =BA6/AZ6 -> #DIV/0! | BC6: =AZ6-BA6 -> 0 | BD6: =BC6/AZ6 -> #DIV/0! | BG6: =BF6/BE6 -> #DIV/0! | BH6: =BE6-BF6 -> 0 | BI6: =BH6/BE6 -> #DIV/0! | BJ6: =B6+G6+L6+Q6+V6+AA6+AF6+AK6+AP6+AU6+AZ6+BE6 -> 142 | BK6: =C6+H6+M6+R6+W6+AB6+AG6+AL6+AQ6+AV6+BA6+BF6 -> 49 | BL6: =BK6/BJ6 -> 0.34507042 | BM6: =BJ6-BK6 -> 93 | BN6: =BM6/BJ6 -> 0.65492958
A7: PERINTHALMANNA | B7: 18 | C7: 3 | D7: =C7/B7 -> 0.16666667 | E7: =B7-C7 -> 15 | F7: =E7/B7 -> 0.83333333 | G7: 17 | H7: 7 | I7: =H7/G7 -> 0.41176471 | J7: =G7-H7 -> 10 | K7: =J7/G7 -> 0.58823529 | L7: 11 | M7: 0 | N7: =M7/L7 -> 0 | O7: =L7-M7 -> 11 | P7: =O7/L7 -> 1 | Q7: 16 | R7: 2 | S7: =R7/Q7 -> 0.125 | T7: =Q7-R7 -> 14 | U7: =T7/Q7 -> 0.875 | V7: 23 | W7: 1 | X7: =W7/V7 -> 0.043478261 | Y7: =V7-W7 -> 22 | Z7: =Y7/V7 -> 0.95652174 | AA7: 12 | AB7: 1 | AC7: =AB7/AA7 -> 0.083333333 | AD7: =AA7-AB7 -> 11 | AE7: =AD7/AA7 -> 0.91666667 | AF7: 16 | AG7: 2 | AH7: =AG7/AF7 -> 0.125 | AI7: =AF7-AG7 -> 14 | AJ7: =AI7/AF7 -> 0.875 | AK7: 17 | AL7: 3 | AM7: =AL7/AK7 -> 0.17647059 | AN7: =AK7-AL7 -> 14 | AO7: =AN7/AK7 -> 0.82352941 | AP7: 16 | AQ7: 4 | AR7: =AQ7/AP7 -> 0.25 | AS7: =AP7-AQ7 -> 12 | AT7: =AS7/AP7 -> 0.75 | AU7: 5 | AV7: 1 | AW7: =AV7/AU7 -> 0.2 | AX7: =AU7-AV7 -> 4 | AY7: =AX7/AU7 -> 0.8 | BB7: =BA7/AZ7 -> #DIV/0! | BC7: =AZ7-BA7 -> 0 | BD7: =BC7/AZ7 -> #DIV/0! | BG7: =BF7/BE7 -> #DIV/0! | BH7: =BE7-BF7 -> 0 | BI7: =BH7/BE7 -> #DIV/0! | BJ7: =B7+G7+L7+Q7+V7+AA7+AF7+AK7+AP7+AU7+AZ7+BE7 -> 151 | BK7: =C7+H7+M7+R7+W7+AB7+AG7+AL7+AQ7+AV7+BA7+BF7 -> 24 | BL7: =BK7/BJ7 -> 0.1589404 | BM7: =BJ7-BK7 -> 127 | BN7: =BM7/BJ7 -> 0.8410596
A8: THIRUR | B8: 36 | C8: 5 | D8: =C8/B8 -> 0.13888889 | E8: =B8-C8 -> 31 | F8: =E8/B8 -> 0.86111111 | G8: 19 | H8: 4 | I8: =H8/G8 -> 0.21052632 | J8: =G8-H8 -> 15 | K8: =J8/G8 -> 0.78947368 | L8: 18 | M8: 5 | N8: =M8/L8 -> 0.27777778 | O8: =L8-M8 -> 13 | P8: =O8/L8 -> 0.72222222 | Q8: 31 | R8: 7 | S8: =R8/Q8 -> 0.22580645 | T8: =Q8-R8 -> 24 | U8: =T8/Q8 -> 0.77419355 | V8: 35 | W8: 9 | X8: =W8/V8 -> 0.25714286 | Y8: =V8-W8 -> 26 | Z8: =Y8/V8 -> 0.74285714 | AA8: 28 | AB8: 4 | AC8: =AB8/AA8 -> 0.14285714 | AD8: =AA8-AB8 -> 24 | AE8: =AD8/AA8 -> 0.85714286 | AF8: 32 | AG8: 6 | AH8: =AG8/AF8 -> 0.1875 | AI8: =AF8-AG8 -> 26 | AJ8: =AI8/AF8 -> 0.8125 | AK8: 44 | AL8: 7 | AM8: =AL8/AK8 -> 0.15909091 | AN8: =AK8-AL8 -> 37 | AO8: =AN8/AK8 -> 0.84090909 | AP8: 36 | AQ8: 7 | AR8: =AQ8/AP8 -> 0.19444444 | AS8: =AP8-AQ8 -> 29 | AT8: =AS8/AP8 -> 0.80555556 | AU8: 11 | AV8: 4 | AW8: =AV8/AU8 -> 0.36363636 | AX8: =AU8-AV8 -> 7 | AY8: =AX8/AU8 -> 0.63636364 | BB8: =BA8/AZ8 -> #DIV/0! | BC8: =AZ8-BA8 -> 0 | BD8: =BC8/AZ8 -> #DIV/0! | BG8: =BF8/BE8 -> #DIV/0! | BH8: =BE8-BF8 -> 0 | BI8: =BH8/BE8 -> #DIV/0! | BJ8: =B8+G8+L8+Q8+V8+AA8+AF8+AK8+AP8+AU8+AZ8+BE8 -> 290 | BK8: =C8+H8+M8+R8+W8+AB8+AG8+AL8+AQ8+AV8+BA8+BF8 -> 58 | BL8: =BK8/BJ8 -> 0.2 | BM8: =BJ8-BK8 -> 232 | BN8: =BM8/BJ8 -> 0.8
A9: THIRURANGADI | B9: 31 | C9: 7 | D9: =C9/B9 -> 0.22580645 | E9: =B9-C9 -> 24 | F9: =E9/B9 -> 0.77419355 | G9: 17 | H9: 6 | I9: =H9/G9 -> 0.35294118 | J9: =G9-H9 -> 11 | K9: =J9/G9 -> 0.64705882 | L9: 32 | M9: 16 | N9: =M9/L9 -> 0.5 | O9: =L9-M9 -> 16 | P9: =O9/L9 -> 0.5 | Q9: 34 | R9: 8 | S9: =R9/Q9 -> 0.23529412 | T9: =Q9-R9 -> 26 | U9: =T9/Q9 -> 0.76470588 | V9: 30 | W9: 10 | X9: =W9/V9 -> 0.33333333 | Y9: =V9-W9 -> 20 | Z9: =Y9/V9 -> 0.66666667 | AA9: 20 | AB9: 14 | AC9: =AB9/AA9 -> 0.7 | AD9: =AA9-AB9 -> 6 | AE9: =AD9/AA9 -> 0.3 | AF9: 19 | AG9: 11 | AH9: =AG9/AF9 -> 0.57894737 | AI9: =AF9-AG9 -> 8 | AJ9: =AI9/AF9 -> 0.42105263 | AK9: 26 | AL9: 5 | AM9: =AL9/AK9 -> 0.19230769 | AN9: =AK9-AL9 -> 21 | AO9: =AN9/AK9 -> 0.80769231 | AP9: 27 | AQ9: 12 | AR9: =AQ9/AP9 -> 0.44444444 | AS9: =AP9-AQ9 -> 15 | AT9: =AS9/AP9 -> 0.55555556 | AU9: 12 | AV9: 9 | AW9: =AV9/AU9 -> 0.75 | AX9: =AU9-AV9 -> 3 | AY9: =AX9/AU9 -> 0.25 | BB9: =BA9/AZ9 -> #DIV/0! | BC9: =AZ9-BA9 -> 0 | BD9: =BC9/AZ9 -> #DIV/0! | BG9: =BF9/BE9 -> #DIV/0! | BH9: =BE9-BF9 -> 0 | BI9: =BH9/BE9 -> #DIV/0! | BJ9: =B9+G9+L9+Q9+V9+AA9+AF9+AK9+AP9+AU9+AZ9+BE9 -> 248 | BK9: =C9+H9+M9+R9+W9+AB9+AG9+AL9+AQ9+AV9+BA9+BF9 -> 98 | BL9: =BK9/BJ9 -> 0.39516129 | BM9: =BJ9-BK9 -> 150 | BN9: =BM9/BJ9 -> 0.60483871
A10: PONNANI | B10: 10 | C10: 2 | D10: =C10/B10 -> 0.2 | E10: =B10-C10 -> 8 | F10: =E10/B10 -> 0.8 | G10: 13 | H10: 3 | I10: =H10/G10 -> 0.23076923 | J10: =G10-H10 -> 10 | K10: =J10/G10 -> 0.76923077 | L10: 9 | M10: 1 | N10: =M10/L10 -> 0.11111111 | O10: =L10-M10 -> 8 | P10: =O10/L10 -> 0.88888889 | Q10: 13 | R10: 2 | S10: =R10/Q10 -> 0.15384615 | T10: =Q10-R10 -> 11 | U10: =T10/Q10 -> 0.84615385 | V10: 11 | W10: 2 | X10: =W10/V10 -> 0.18181818 | Y10: =V10-W10 -> 9 | Z10: =Y10/V10 -> 0.81818182 | AA10: 11 | AB10: 3 | AC10: =AB10/AA10 -> 0.27272727 | AD10: =AA10-AB10 -> 8 | AE10: =AD10/AA10 -> 0.72727273 | AF10: 6 | AG10: 6 | AH10: =AG10/AF10 -> 1 | AI10: =AF10-AG10 -> 0 | AJ10: =AI10/AF10 -> 0 | AK10: 7 | AL10: 4 | AM10: =AL10/AK10 -> 0.57142857 | AN10: =AK10-AL10 -> 3 | AO10: =AN10/AK10 -> 0.42857143 | AP10: 6 | AQ10: 9 | AR10: =AQ10/AP10 -> 1.5 | AS10: =AP10-AQ10 -> -3 | AT10: =AS10/AP10 -> -0.5 | AU10: 8 | AV10: 2 | AW10: =AV10/AU10 -> 0.25 | AX10: =AU10-AV10 -> 6 | AY10: =AX10/AU10 -> 0.75 | BB10: =BA10/AZ10 -> #DIV/0! | BC10: =AZ10-BA10 -> 0 | BD10: =BC10/AZ10 -> #DIV/0! | BG10: =BF10/BE10 -> #DIV/0! | BH10: =BE10-BF10 -> 0 | BI10: =BH10/BE10 -> #DIV/0! | BJ10: =B10+G10+L10+Q10+V10+AA10+AF10+AK10+AP10+AU10+AZ10+BE10 -> 94 | BK10: =C10+H10+M10+R10+W10+AB10+AG10+AL10+AQ10+AV10+BA10+BF10 -> 34 | BL10: =BK10/BJ10 -> 0.36170213 | BM10: =BJ10-BK10 -> 60 | BN10: =BM10/BJ10 -> 0.63829787
A11: OTHER | H11: 3 | M11: 3 | R11: 2 | W11: 5 | AB11: 4 | AG11: 7 | AL11: 4 | AQ11: 2 | AV11: 2 | BK11: =C11+H11+M11+R11+W11+AB11+AG11+AL11+AQ11+AV11+BA11+BF11 -> 32
A12: TOTAL | B12: =SUM(B4:B10) -> 148 | C12: =SUM(C4:C10) -> 30 | D12: =C12/B12 -> 0.2027027 | E12: =B12-C12 -> 118 | F12: =E12/B12 -> 0.7972973 | G12: =SUM(G4:G10) -> 117 | H12: =SUM(H4:H10) -> 37 | I12: =H12/G12 -> 0.31623932 | J12: =G12-H12 -> 80 | K12: =J12/G12 -> 0.68376068 | L12: =SUM(L4:L10) -> 121 | M12: =SUM(M4:M10) -> 39 | N12: =M12/L12 -> 0.32231405 | O12: =L12-M12 -> 82 | P12: =O12/L12 -> 0.67768595 | Q12: =SUM(Q4:Q10) -> 140 | R12: =SUM(R4:R10) -> 36 | S12: =R12/Q12 -> 0.25714286 | T12: =Q12-R12 -> 104 | U12: =T12/Q12 -> 0.74285714 | V12: =SUM(V4:V10) -> 143 | W12: =SUM(W4:W10) -> 34 | X12: =W12/V12 -> 0.23776224 | Y12: =V12-W12 -> 109 | Z12: =Y12/V12 -> 0.76223776 | AA12: =SUM(AA4:AA10) -> 123 | AB12: =SUM(AB4:AB10) -> 34 | AC12: =AB12/AA12 -> 0.27642276 | AD12: =AA12-AB12 -> 89 | AE12: =AD12/AA12 -> 0.72357724 | AF12: =SUM(AF4:AF10) -> 120 | AG12: =SUM(AG4:AG10) -> 33 | AH12: =AG12/AF12 -> 0.275 | AI12: =AF12-AG12 -> 87 | AJ12: =AI12/AF12 -> 0.725 | AK12: =SUM(AK4:AK10) -> 138 | AL12: =SUM(AL4:AL10) -> 36 | AM12: =AL12/AK12 -> 0.26086957 | AN12: =AK12-AL12 -> 102 | AO12: =AN12/AK12 -> 0.73913043 | AP12: =SUM(AP4:AP10) -> 143 | AQ12: =SUM(AQ4:AQ10) -> 53 | AR12: =AQ12/AP12 -> 0.37062937 | AS12: =AP12-AQ12 -> 90 | AT12: =AS12/AP12 -> 0.62937063 | AU12: =SUM(AU4:AU10) -> 69 | AV12: =SUM(AV4:AV10) -> 21 | AW12: =AV12/AU12 -> 0.30434783 | AX12: =AU12-AV12 -> 48 | AY12: =AX12/AU12 -> 0.69565217 | AZ12: =SUM(AZ4:AZ10) -> 0 | BA12: =SUM(BA4:BA10) -> 0 | BB12: =BA12/AZ12 -> #DIV/0! | BC12: =AZ12-BA12 -> 0 | BD12: =BC12/AZ12 -> #DIV/0! | BE12: =SUM(BE4:BE10) -> 0 | BF12: =SUM(BF4:BF10) -> 0 | BG12: =BF12/BE12 -> #DIV/0! | BH12: =BE12-BF12 -> 0 | BI12: =BH12/BE12 -> #DIV/0! | BJ12: =SUM(BJ4:BJ10) -> 1262 | BK12: =SUM(BK4:BK10) -> 353 | BL12: =BK12/BJ12 -> 0.27971474 | BM12: =BJ12-BK12 -> 909 | BN12: =BM12/BJ12 -> 0.72028526
A14: RTO WISE REPORT - 2023
B15: JAN | G15: FEB | L15: MAR | Q15: APR | V15: MAY | AA15: JUN | AF15: JUL | AK15: AUG | AP15: SEP | AU15: OCT | AZ15: NOV | BE15: DEC | BJ15: 2023
A16: RTO | B16: TOTAL | C16: CLASSIC | D16: % | E16: OTHERS | F16: % | G16: TOTAL | H16: CLASSIC | I16: % | J16: OTHERS | K16: % | L16: TOTAL | M16: CLASSIC | N16: % | O16: OTHERS | P16: % | Q16: TOTAL | R16: CLASSIC | S16: % | T16: OTHERS | U16: % | V16: TOTAL | W16: CLASSIC | X16: % | Y16: OTHERS | Z16: % | AA16: TOTAL | AB16: CLASSIC | AC16: % | AD16: OTHERS | AE16: % | AF16: TOTAL | AG16: CLASSIC | AH16: % | AI16: OTHERS | AJ16: % | AK16: TOTAL | AL16: CLASSIC | AM16: % | AN16: OTHERS | AO16: % | AP16: TOTAL | AQ16: CLASSIC | AR16: % | AS16: OTHERS | AT16: % | AU16: TOTAL | AV16: CLASSIC | AW16: % | AX16: OTHERS | AY16: % | AZ16: TOTAL | BA16: CLASSIC | BB16: % | BC16: OTHERS | BD16: % | BE16: TOTAL | BF16: CLASSIC | BG16: % | BH16: OTHERS | BI16: % | BJ16: TOTAL | BK16: CLASSIC | BL16: % | BM16: OTHERS | BN16: %
A17: MALAPPURAM | B17: 13 | C17: 8 | D17: =C17/B17 -> 0.61538462 | E17: =B17-C17 -> 5 | F17: =E17/B17 -> 0.38461538 | G17: 19 | H17: 5 | I17: =H17/G17 -> 0.26315789 | J17: =G17-H17 -> 14 | K17: =J17/G17 -> 0.73684211 | L17: 19 | M17: 8 | N17: =M17/L17 -> 0.42105263 | O17: =L17-M17 -> 11 | P17: =O17/L17 -> 0.57894737 | Q17: 6 | R17: 3 | S17: =R17/Q17 -> 0.5 | T17: =Q17-R17 -> 3 | U17: =T17/Q17 -> 0.5 | V17: 27 | W17: 5 | X17: =W17/V17 -> 0.18518519 | Y17: =V17-W17 -> 22 | Z17: =Y17/V17 -> 0.81481481 | AA17: 15 | AB17: 5 | AC17: =AB17/AA17 -> 0.33333333 | AD17: =AA17-AB17 -> 10 | AE17: =AD17/AA17 -> 0.66666667 | AF17: 19 | AG17: 9 | AH17: =AG17/AF17 -> 0.47368421 | AI17: =AF17-AG17 -> 10 | AJ17: =AI17/AF17 -> 0.52631579 | AK17: 36 | AL17: 12 | AM17: =AL17/AK17 -> 0.33333333 | AN17: =AK17-AL17 -> 24 | AO17: =AN17/AK17 -> 0.66666667 | AP17: 33 | AQ17: 4 | AR17: =AQ17/AP17 -> 0.12121212 | AS17: =AP17-AQ17 -> 29 | AT17: =AS17/AP17 -> 0.87878788 | AU17: 15 | AV17: 3 | AW17: =AV17/AU17 -> 0.2 | AX17: =AU17-AV17 -> 12 | AY17: =AX17/AU17 -> 0.8 | AZ17: 17 | BA17: 8 | BB17: =BA17/AZ17 -> 0.47058824 | BC17: =AZ17-BA17 -> 9 | BD17: =BC17/AZ17 -> 0.52941176 | BE17: 19 | BF17: 12 | BG17: =BF17/BE17 -> 0.63157895 | BH17: =BE17-BF17 -> 7 | BI17: =BH17/BE17 -> 0.36842105 | BJ17: =B17+G17+L17+Q17+V17+AA17+AF17+AK17+AP17+AU17+AZ17+BE17 -> 238 | BK17: =C17+H17+M17+R17+W17+AB17+AG17+AL17+AQ17+AV17+BA17+BF17 -> 82 | BL17: =BK17/BJ17 -> 0.34453782 | BM17: =BJ17-BK17 -> 156 | BN17: =BM17/BJ17 -> 0.65546218
A18: KONDOTTY | B18: 19 | C18: 1 | D18: =C18/B18 -> 0.052631579 | E18: =B18-C18 -> 18 | F18: =E18/B18 -> 0.94736842 | G18: 8 | H18: 0 | I18: =H18/G18 -> 0 | J18: =G18-H18 -> 8 | K18: =J18/G18 -> 1 | L18: 22 | M18: 8 | N18: =M18/L18 -> 0.36363636 | O18: =L18-M18 -> 14 | P18: =O18/L18 -> 0.63636364 | Q18: 12 | R18: 1 | S18: =R18/Q18 -> 0.083333333 | T18: =Q18-R18 -> 11 | U18: =T18/Q18 -> 0.91666667 | V18: 10 | W18: 0 | X18: =W18/V18 -> 0 | Y18: =V18-W18 -> 10 | Z18: =Y18/V18 -> 1 | AA18: 12 | AB18: 3 | AC18: =AB18/AA18 -> 0.25 | AD18: =AA18-AB18 -> 9 | AE18: =AD18/AA18 -> 0.75 | AF18: 14 | AG18: 6 | AH18: =AG18/AF18 -> 0.42857143 | AI18: =AF18-AG18 -> 8 | AJ18: =AI18/AF18 -> 0.57142857 | AK18: 19 | AL18: 7 | AM18: =AL18/AK18 -> 0.36842105 | AN18: =AK18-AL18 -> 12 | AO18: =AN18/AK18 -> 0.63157895 | AP18: 26 | AQ18: 2 | AR18: =AQ18/AP18 -> 0.076923077 | AS18: =AP18-AQ18 -> 24 | AT18: =AS18/AP18 -> 0.92307692 | AU18: 19 | AV18: 2 | AW18: =AV18/AU18 -> 0.10526316 | AX18: =AU18-AV18 -> 17 | AY18: =AX18/AU18 -> 0.89473684 | AZ18: 17 | BA18: 6 | BB18: =BA18/AZ18 -> 0.35294118 | BC18: =AZ18-BA18 -> 11 | BD18: =BC18/AZ18 -> 0.64705882 | BE18: 15 | BF18: 7 | BG18: =BF18/BE18 -> 0.46666667 | BH18: =BE18-BF18 -> 8 | BI18: =BH18/BE18 -> 0.53333333 | BJ18: =B18+G18+L18+Q18+V18+AA18+AF18+AK18+AP18+AU18+AZ18+BE18 -> 193 | BK18: =C18+H18+M18+R18+W18+AB18+AG18+AL18+AQ18+AV18+BA18+BF18 -> 43 | BL18: =BK18/BJ18 -> 0.22279793 | BM18: =BJ18-BK18 -> 150 | BN18: =BM18/BJ18 -> 0.77720207
A19: NILAMBUR | B19: 8 | C19: 1 | D19: =C19/B19 -> 0.125 | E19: =B19-C19 -> 7 | F19: =E19/B19 -> 0.875 | G19: 5 | H19: 2 | I19: =H19/G19 -> 0.4 | J19: =G19-H19 -> 3 | K19: =J19/G19 -> 0.6 | L19: 23 | M19: 7 | N19: =M19/L19 -> 0.30434783 | O19: =L19-M19 -> 16 | P19: =O19/L19 -> 0.69565217 | Q19: 5 | R19: 2 | S19: =R19/Q19 -> 0.4 | T19: =Q19-R19 -> 3 | U19: =T19/Q19 -> 0.6 | V19: 17 | W19: 3 | X19: =W19/V19 -> 0.17647059 | Y19: =V19-W19 -> 14 | Z19: =Y19/V19 -> 0.82352941 | AA19: 15 | AB19: 1 | AC19: =AB19/AA19 -> 0.066666667 | AD19: =AA19-AB19 -> 14 | AE19: =AD19/AA19 -> 0.93333333 | AF19: 9 | AG19: 5 | AH19: =AG19/AF19 -> 0.55555556 | AI19: =AF19-AG19 -> 4 | AJ19: =AI19/AF19 -> 0.44444444 | AK19: 21 | AL19: 8 | AM19: =AL19/AK19 -> 0.38095238 | AN19: =AK19-AL19 -> 13 | AO19: =AN19/AK19 -> 0.61904762 | AP19: 26 | AQ19: 7 | AR19: =AQ19/AP19 -> 0.26923077 | AS19: =AP19-AQ19 -> 19 | AT19: =AS19/AP19 -> 0.73076923 | AU19: 10 | AV19: 3 | AW19: =AV19/AU19 -> 0.3 | AX19: =AU19-AV19 -> 7 | AY19: =AX19/AU19 -> 0.7 | AZ19: 13 | BA19: 3 | BB19: =BA19/AZ19 -> 0.23076923 | BC19: =AZ19-BA19 -> 10 | BD19: =BC19/AZ19 -> 0.76923077 | BE19: 14 | BF19: 1 | BG19: =BF19/BE19 -> 0.071428571 | BH19: =BE19-BF19 -> 13 | BI19: =BH19/BE19 -> 0.92857143 | BJ19: =B19+G19+L19+Q19+V19+AA19+AF19+AK19+AP19+AU19+AZ19+BE19 -> 166 | BK19: =C19+H19+M19+R19+W19+AB19+AG19+AL19+AQ19+AV19+BA19+BF19 -> 43 | BL19: =BK19/BJ19 -> 0.25903614 | BM19: =BJ19-BK19 -> 123 | BN19: =BM19/BJ19 -> 0.74096386
A20: PERINTHALMANNA | B20: 10 | C20: 0 | D20: =C20/B20 -> 0 | E20: =B20-C20 -> 10 | F20: =E20/B20 -> 1 | G20: 15 | H20: 1 | I20: =H20/G20 -> 0.066666667 | J20: =G20-H20 -> 14 | K20: =J20/G20 -> 0.93333333 | L20: 22 | M20: 4 | N20: =M20/L20 -> 0.18181818 | O20: =L20-M20 -> 18 | P20: =O20/L20 -> 0.81818182 | Q20: 10 | R20: 0 | S20: =R20/Q20 -> 0 | T20: =Q20-R20 -> 10 | U20: =T20/Q20 -> 1 | V20: 11 | W20: 1 | X20: =W20/V20 -> 0.090909091 | Y20: =V20-W20 -> 10 | Z20: =Y20/V20 -> 0.90909091 | AA20: 16 | AB20: 3 | AC20: =AB20/AA20 -> 0.1875 | AD20: =AA20-AB20 -> 13 | AE20: =AD20/AA20 -> 0.8125 | AF20: 20 | AG20: 3 | AH20: =AG20/AF20 -> 0.15 | AI20: =AF20-AG20 -> 17 | AJ20: =AI20/AF20 -> 0.85 | AK20: 12 | AL20: 1 | AM20: =AL20/AK20 -> 0.083333333 | AN20: =AK20-AL20 -> 11 | AO20: =AN20/AK20 -> 0.91666667 | AP20: 18 | AQ20: 2 | AR20: =AQ20/AP20 -> 0.11111111 | AS20: =AP20-AQ20 -> 16 | AT20: =AS20/AP20 -> 0.88888889 | AU20: 13 | AV20: 4 | AW20: =AV20/AU20 -> 0.30769231 | AX20: =AU20-AV20 -> 9 | AY20: =AX20/AU20 -> 0.69230769 | AZ20: 6 | BA20: 0 | BB20: =BA20/AZ20 -> 0 | BC20: =AZ20-BA20 -> 6 | BD20: =BC20/AZ20 -> 1 | BE20: 10 | BF20: 3 | BG20: =BF20/BE20 -> 0.3 | BH20: =BE20-BF20 -> 7 | BI20: =BH20/BE20 -> 0.7 | BJ20: =B20+G20+L20+Q20+V20+AA20+AF20+AK20+AP20+AU20+AZ20+BE20 -> 163 | BK20: =C20+H20+M20+R20+W20+AB20+AG20+AL20+AQ20+AV20+BA20+BF20 -> 22 | BL20: =BK20/BJ20 -> 0.13496933 | BM20: =BJ20-BK20 -> 141 | BN20: =BM20/BJ20 -> 0.86503067
A21: THIRUR | B21: 25 | C21: 3 | D21: =C21/B21 -> 0.12 | E21: =B21-C21 -> 22 | F21: =E21/B21 -> 0.88 | G21: 24 | H21: 7 | I21: =H21/G21 -> 0.29166667 | J21: =G21-H21 -> 17 | K21: =J21/G21 -> 0.70833333 | L21: 32 | M21: 6 | N21: =M21/L21 -> 0.1875 | O21: =L21-M21 -> 26 | P21: =O21/L21 -> 0.8125 | Q21: 22 | R21: 4 | S21: =R21/Q21 -> 0.18181818 | T21: =Q21-R21 -> 18 | U21: =T21/Q21 -> 0.81818182 | V21: 17 | W21: 1 | X21: =W21/V21 -> 0.058823529 | Y21: =V21-W21 -> 16 | Z21: =Y21/V21 -> 0.94117647 | AA21: 23 | AB21: 5 | AC21: =AB21/AA21 -> 0.2173913 | AD21: =AA21-AB21 -> 18 | AE21: =AD21/AA21 -> 0.7826087 | AF21: 25 | AG21: 6 | AH21: =AG21/AF21 -> 0.24 | AI21: =AF21-AG21 -> 19 | AJ21: =AI21/AF21 -> 0.76 | AK21: 22 | AL21: 10 | AM21: =AL21/AK21 -> 0.45454545 | AN21: =AK21-AL21 -> 12 | AO21: =AN21/AK21 -> 0.54545455 | AP21: 44 | AQ21: 4 | AR21: =AQ21/AP21 -> 0.090909091 | AS21: =AP21-AQ21 -> 40 | AT21: =AS21/AP21 -> 0.90909091 | AU21: 35 | AV21: 2 | AW21: =AV21/AU21 -> 0.057142857 | AX21: =AU21-AV21 -> 33 | AY21: =AX21/AU21 -> 0.94285714 | AZ21: 29 | BA21: 5 | BB21: =BA21/AZ21 -> 0.17241379 | BC21: =AZ21-BA21 -> 24 | BD21: =BC21/AZ21 -> 0.82758621 | BE21: 26 | BF21: 4 | BG21: =BF21/BE21 -> 0.15384615 | BH21: =BE21-BF21 -> 22 | BI21: =BH21/BE21 -> 0.84615385 | BJ21: =B21+G21+L21+Q21+V21+AA21+AF21+AK21+AP21+AU21+AZ21+BE21 -> 324 | BK21: =C21+H21+M21+R21+W21+AB21+AG21+AL21+AQ21+AV21+BA21+BF21 -> 57 | BL21: =BK21/BJ21 -> 0.17592593 | BM21: =BJ21-BK21 -> 267 | BN21: =BM21/BJ21 -> 0.82407407
A22: THIRURANGADI | B22: 27 | C22: 12 | D22: =C22/B22 -> 0.44444444 | E22: =B22-C22 -> 15 | F22: =E22/B22 -> 0.55555556 | G22: 26 | H22: 4 | I22: =H22/G22 -> 0.15384615 | J22: =G22-H22 -> 22 | K22: =J22/G22 -> 0.84615385 | L22: 25 | M22: 9 | N22: =M22/L22 -> 0.36 | O22: =L22-M22 -> 16 | P22: =O22/L22 -> 0.64 | Q22: 11 | R22: 2 | S22: =R22/Q22 -> 0.18181818 | T22: =Q22-R22 -> 9 | U22: =T22/Q22 -> 0.81818182 | V22: 25 | W22: 5 | X22: =W22/V22 -> 0.2 | Y22: =V22-W22 -> 20 | Z22: =Y22/V22 -> 0.8 | AA22: 23 | AB22: 13 | AC22: =AB22/AA22 -> 0.56521739 | AD22: =AA22-AB22 -> 10 | AE22: =AD22/AA22 -> 0.43478261 | AF22: 29 | AG22: 4 | AH22: =AG22/AF22 -> 0.13793103 | AI22: =AF22-AG22 -> 25 | AJ22: =AI22/AF22 -> 0.86206897 | AK22: 26 | AL22: 14 | AM22: =AL22/AK22 -> 0.53846154 | AN22: =AK22-AL22 -> 12 | AO22: =AN22/AK22 -> 0.46153846 | AP22: 41 | AQ22: 7 | AR22: =AQ22/AP22 -> 0.17073171 | AS22: =AP22-AQ22 -> 34 | AT22: =AS22/AP22 -> 0.82926829 | AU22: 28 | AV22: 11 | AW22: =AV22/AU22 -> 0.39285714 | AX22: =AU22-AV22 -> 17 | AY22: =AX22/AU22 -> 0.60714286 | AZ22: 22 | BA22: 10 | BB22: =BA22/AZ22 -> 0.45454545 | BC22: =AZ22-BA22 -> 12 | BD22: =BC22/AZ22 -> 0.54545455 | BE22: 19 | BF22: 12 | BG22: =BF22/BE22 -> 0.63157895 | BH22: =BE22-BF22 -> 7 | BI22: =BH22/BE22 -> 0.36842105 | BJ22: =B22+G22+L22+Q22+V22+AA22+AF22+AK22+AP22+AU22+AZ22+BE22 -> 302 | BK22: =C22+H22+M22+R22+W22+AB22+AG22+AL22+AQ22+AV22+BA22+BF22 -> 103 | BL22: =BK22/BJ22 -> 0.3410596 | BM22: =BJ22-BK22 -> 199 | BN22: =BM22/BJ22 -> 0.6589404
A23: PONNANI | B23: 8 | C23: 1 | D23: =C23/B23 -> 0.125 | E23: =B23-C23 -> 7 | F23: =E23/B23 -> 0.875 | G23: 6 | H23: 0 | I23: =H23/G23 -> 0 | J23: =G23-H23 -> 6 | K23: =J23/G23 -> 1 | L23: 14 | M23: 3 | N23: =M23/L23 -> 0.21428571 | O23: =L23-M23 -> 11 | P23: =O23/L23 -> 0.78571429 | Q23: 12 | R23: 2 | S23: =R23/Q23 -> 0.16666667 | T23: =Q23-R23 -> 10 | U23: =T23/Q23 -> 0.83333333 | V23: 8 | W23: 1 | X23: =W23/V23 -> 0.125 | Y23: =V23-W23 -> 7 | Z23: =Y23/V23 -> 0.875 | AA23: 10 | AB23: 2 | AC23: =AB23/AA23 -> 0.2 | AD23: =AA23-AB23 -> 8 | AE23: =AD23/AA23 -> 0.8 | AF23: 10 | AG23: 4 | AH23: =AG23/AF23 -> 0.4 | AI23: =AF23-AG23 -> 6 | AJ23: =AI23/AF23 -> 0.6 | AK23: 11 | AL23: 5 | AM23: =AL23/AK23 -> 0.45454545 | AN23: =AK23-AL23 -> 6 | AO23: =AN23/AK23 -> 0.54545455 | AP23: 14 | AQ23: 3 | AR23: =AQ23/AP23 -> 0.21428571 | AS23: =AP23-AQ23 -> 11 | AT23: =AS23/AP23 -> 0.78571429 | AU23: 13 | AV23: 7 | AW23: =AV23/AU23 -> 0.53846154 | AX23: =AU23-AV23 -> 6 | AY23: =AX23/AU23 -> 0.46153846 | AZ23: 9 | BA23: 1 | BB23: =BA23/AZ23 -> 0.11111111 | BC23: =AZ23-BA23 -> 8 | BD23: =BC23/AZ23 -> 0.88888889 | BE23: 6 | BF23: 2 | BG23: =BF23/BE23 -> 0.33333333 | BH23: =BE23-BF23 -> 4 | BI23: =BH23/BE23 -> 0.66666667 | BJ23: =B23+G23+L23+Q23+V23+AA23+AF23+AK23+AP23+AU23+AZ23+BE23 -> 121 | BK23: =C23+H23+M23+R23+W23+AB23+AG23+AL23+AQ23+AV23+BA23+BF23 -> 31 | BL23: =BK23/BJ23 -> 0.25619835 | BM23: =BJ23-BK23 -> 90 | BN23: =BM23/BJ23 -> 0.74380165
A24: OTHER | C24: 4 | H24: 2 | M24: 4 | R24: 2 | W24: 3 | AG24: 5 | AL24: 5 | AQ24: 3 | AV24: 3 | BA24: 4 | BF24: 6 | BK24: =C24+H24+M24+R24+W24+AB24+AG24+AL24+AQ24+AV24+BA24+BF24 -> 41
